<?xml version="1.0"?>
<robot xmlns:xacro="http://www.ros.org/wiki/xacro"
  xmlns:sensor="http://playerstage.sourceforge.net/gazebo/xmlschema/#sensor"
  xmlns:controller="http://playerstage.sourceforge.net/gazebo/xmlschema/#controller"
  xmlns:interface="http://playerstage.sourceforge.net/gazebo/xmlschema/#interface"
  name="DRC_HEAD">


  <!--<link name="base_footprint">
    <visual>
      <origin xyz="0 0 0" rpy="0 0 0" />
      <geometry>
        <box size="0.001 0.001 0.001"/>
      </geometry>
    </visual>
  </link>

  <joint name="base_footprint_joint" type="fixed">
    <origin xyz="0 0 0" rpy="0 0 0" />
    <parent link="base_footprint" />
    <child link="Body_Head" />
  </joint>-->

  <link name="Body_Head">
    <inertial>
      <origin
        xyz="-0.0080768 0.0056186 0.13872"
        rpy="0 0 0" />
      <mass
        value="0.69065" />
      <inertia
        ixx="0.0068275"
        ixy="0.00011826"
        ixz="0.0014243"
        iyy="0.0060857"
        iyz="-0.00045042"
        izz="0.0053323" />
    </inertial>
    <visual>
      <origin
        xyz="0 0 0"
        rpy="0 0 0" />
      <geometry>
        <mesh filename="package://drc_plugin/meshes/Body_Head.STL" />
      </geometry>
      <material
        name="">
        <color
          rgba="0.79216 0.81961 0.93333 1" />
      </material>
    </visual>
    <collision>
      <origin
        xyz="0 0 0"
        rpy="0 0 0" />
      <geometry>
        <mesh filename="package://drc_plugin/meshes/Body_Head.STL" />
      </geometry>
    </collision>
  </link>

  <joint name="Head_Sensor" type="revolute">
    <origin
      xyz="0.085 0.0425 0.165"
      rpy="0 0 0" />
    <parent
      link="Body_Head" />
    <child
      link="Body_Hokuyo" />
    <axis
      xyz="0 1 0" />
    <limit effort="100000" velocity="1.0" lower="-5" upper="5" />
    <dynamics damping="200" friction="200" />
  </joint>

  <link name="Body_Hokuyo">
    <inertial>
      <origin
        xyz="0.0010159 -0.041037 0.0011902"
        rpy="0 0 0"/>
      <mass
        value="0.34186" />
      <inertia
        ixx="0.00046452"
        ixy="-4.8449E-06"
        ixz="-2.3351E-05"
        iyy="0.00048884"
        iyz="1.6828E-06"
        izz="0.00020206" />
    </inertial>
    <collision>
      <origin xyz="0 0 0" rpy="0 0 0"/>
      <geometry>
        <mesh filename="package://drc_plugin/meshes/Body_Hokuyo.STL"/>
      </geometry>
    </collision>
    <visual>
      <origin xyz="0 0 0" rpy="0 0 0"/>
      <geometry>
        <mesh filename="package://drc_plugin/meshes/Body_Hokuyo.STL"/>
      </geometry>
      <material
        name="">
        <color
          rgba="0.79216 0.81961 0.93333 1" />
      </material>
    </visual>
  </link>


</robot>
