<?xml version="1.0"?>

<sdf version='1.4'>
  <model name='DRC_hubo'>
    <pose>0 0 1.07 0 -0 0</pose>

    <link name='Body_TORSO'>
      <pose>0 0 0 0 0 0</pose>
      <inertial>
        <pose>0.000373 0.000832 0.360257 0 -0 0</pose>
        <mass>18.236</mass>
        <inertia>
          <ixx>0.19794</ixx>
          <ixy>6.4e-05</ixy>
          <ixz>-0.001125</ixz>
          <iyy>0.155811</iyy>
          <iyz>0.000284</iyz>
          <izz>0.117584</izz>
        </inertia>
      </inertial>

      <collision name='Body_TORSO_collision'>
        <pose>0 0 0 0 0 0</pose>
        <geometry>
          <mesh>
            <scale>1 1 1</scale>
            <uri>model://DRC_hubo/meshes/Body_TORSO_col.STL</uri>
          </mesh>
        </geometry>
      </collision>

      <visual name='Body_TORSO_visual'>
        <pose>0 0 0 0 -0 0</pose>
        <geometry>
          <mesh>
            <scale>1 1 1</scale>
            <uri>model://DRC_hubo/meshes/Body_TORSO.STL</uri>
          </mesh>
        </geometry>
      </visual>

      <velocity_decay>
        <linear>0</linear>
        <angular>0</angular>
      </velocity_decay>
    </link>

    <link name='Body_LSP'>
      <pose>0 0.242 0.456 0 -0 0</pose>
      <inertial>
        <pose>0.015596 -0.052409 0 0 -0 0</pose>
        <mass>1.6</mass>
        <inertia>
          <ixx>0.005195</ixx>
          <ixy>0.001333</ixy>
          <ixz>1e-08</ixz>
          <iyy>0.004409</iyy>
          <iyz>0</iyz>
          <izz>0.007234</izz>
        </inertia>
      </inertial>

      <collision name='Body_LSP_collision'>
        <pose>0 0 0 0 -0 0</pose>
        <geometry>
          <mesh>
            <scale>1 1 1</scale>
            <uri>model://DRC_hubo/meshes/Body_LSP_col.STL</uri>
          </mesh>
        </geometry>
      </collision>

      <visual name='Body_LSP_visual'>
        <pose>0 0 0 0 -0 0</pose>
        <geometry>
          <mesh>
            <scale>1 1 1</scale>
            <uri>model://DRC_hubo/meshes/Body_LSP.STL</uri>
          </mesh>
        </geometry>
      </visual>

      <velocity_decay>
        <linear>0</linear>
        <angular>0</angular>
      </velocity_decay>
    </link>

    <joint name='LSP' type='revolute'>
      <child>Body_LSP</child>
      <parent>Body_TORSO</parent>
      <axis>
        <xyz>0 1 0</xyz>
        <limit>
          <lower>-5</lower>
          <upper>5</upper>
          <effort>10000000</effort>
          <velocity>100</velocity>
        </limit>
        <dynamics>
          <damping>15</damping> <friction>2</friction>
        </dynamics>
      </axis>
    </joint>

    <link name='Body_LSR'>
      <pose>0 0.242 0.456 1.5044e-11 8.6042e-16 -1.7705e-12</pose>
      <inertial>
        <pose>-0.003104 0.000106 -0.013013 0 -0 0</pose>
        <mass>1.427</mass>
        <inertia>
          <ixx>0.003163</ixx>
          <ixy>6e-06</ixy>
          <ixz>-0.000211</ixz>
          <iyy>0.003689</iyy>
          <iyz>0</iyz>
          <izz>0.001909</izz>
        </inertia>
      </inertial>

      <collision name='Body_LSR_collision'>
        <pose>0 0 0 0 -0 0</pose>
        <geometry>
          <mesh>
            <scale>1 1 1</scale>
            <uri>model://DRC_hubo/meshes/Body_LSR_col.STL</uri>
          </mesh>
        </geometry>
      </collision>

      <visual name='Body_LSR_visual'>
        <pose>0 0 0 0 -0 0</pose>
        <geometry>
          <mesh>
            <scale>1 1 1</scale>
            <uri>model://DRC_hubo/meshes/Body_LSR.STL</uri>
          </mesh>
        </geometry>
      </visual>

      <velocity_decay>
        <linear>0</linear>
        <angular>0</angular>
      </velocity_decay>
    </link>

    <joint name='LSR' type='revolute'>
      <child>Body_LSR</child>
      <parent>Body_LSP</parent>
      <axis>
        <xyz>1 0 0</xyz>
        <limit>
          <lower>-5.14</lower>
          <upper>5.14</upper>
          <effort>10000000</effort>
          <velocity>100</velocity>
        </limit>
        <dynamics>
          <damping>15</damping> <friction>2</friction>
        </dynamics>
      </axis>
    </joint>

    <link name='Body_LSY'>
      <pose>0 0.242 0.456 1.50418e-11 -2.77541e-16 4.05633e-09</pose>
      <inertial>
        <pose>0.00429109 0.00371065 -0.238921 0 -0 0</pose>
        <mass>2.35838</mass>
        <inertia>
          <ixx>0.024139</ixx>
          <ixy>0.000334</ixy>
          <ixz>-0.003948</ixz>
          <iyy>0.024861</iyy>
          <iyz>-0.001103</iyz>
          <izz>0.003447</izz>
        </inertia>
      </inertial>

      <collision name='Body_LSY_collision'>
        <pose>0 0 0 0 -0 0</pose>
        <geometry>
          <mesh>
            <scale>1 1 1</scale>
            <uri>model://DRC_hubo/meshes/Body_LSY_col.STL</uri>
          </mesh>
        </geometry>
      </collision>

      <visual name='Body_LSY_visual'>
        <pose>0 0 0 0 -0 0</pose>
        <geometry>
          <mesh>
            <scale>1 1 1</scale>
            <uri>model://DRC_hubo/meshes/Body_LSY.STL</uri>
          </mesh>
        </geometry>
      </visual>

      <velocity_decay>
        <linear>0</linear>
        <angular>0</angular>
      </velocity_decay>
    </link>

    <joint name='LSY' type='revolute'>
      <child>Body_LSY</child>
      <parent>Body_LSR</parent>
      <axis>
        <xyz>0 0 1</xyz>
        <limit>
          <lower>-5</lower>
          <upper>5</upper>
          <effort>10000000</effort>
          <velocity>100</velocity>
        </limit>
        <dynamics>
          <damping>5</damping> <friction>2</friction>
        </dynamics>
      </axis>
    </joint>

    <link name='Body_LEB'>
      <pose>0.035001 0.24202 0.106 1.50758e-11 -1.5404e-10 4.05633e-09</pose>
      <inertial>
        <pose>-0.019775 0.004924 -0.041836 0 -0 0</pose>
        <mass>0.409464</mass>
        <inertia>
          <ixx>0.001031</ixx>
          <ixy>4e-05</ixy>
          <ixz>0.000277</ixz>
          <iyy>0.001163</iyy>
          <iyz>8.5e-05</iyz>
          <izz>0.00056</izz>
        </inertia>
      </inertial>

      <collision name='Body_LEB_collision'>
        <pose>0 0 0 0 -0 0</pose>
        <geometry>
          <mesh>
            <scale>1 1 1</scale>
            <uri>model://DRC_hubo/meshes/Body_LEB_col.STL</uri>
          </mesh>
        </geometry>
      </collision>

      <visual name='Body_LEB_visual'>
        <pose>0 0 0 0 -0 0</pose>
        <geometry>
          <mesh>
            <scale>1 1 1</scale>
            <uri>model://DRC_hubo/meshes/Body_LEB.STL</uri>
          </mesh>
        </geometry>
      </visual>

      <velocity_decay>
        <linear>0</linear>
        <angular>0</angular>
      </velocity_decay>
    </link>

    <joint name='LEB' type='revolute'>
      <child>Body_LEB</child>
      <parent>Body_LSY</parent>
      <axis>
        <xyz>0 1 0</xyz>
        <limit>
          <lower>-5</lower>
          <upper>5</upper>
          <effort>10000000</effort>
          <velocity>100</velocity>
        </limit>
        <dynamics>
          <damping>8</damping> <friction>2</friction>
        </dynamics>
      </axis>
    </joint>

    <link name='Body_LWY'>
      <pose>1.00005e-06 0.24202 -0.234 1.5041e-11 -1.54041e-10 -3.36547e-08</pose>
      <inertial>
        <pose>5.4e-05 0.001779 0.134651 0 -0 0</pose>
        <mass>1.47</mass>
        <inertia>
          <ixx>0.01302</ixx>
          <ixy>-1e-05</ixy>
          <ixz>4e-5</ixz>
          <iyy>0.012803</iyy>
          <iyz>-0.000388</iyz>
          <izz>0.000862</izz>
        </inertia>
      </inertial>

      <collision name='Body_LWY_collision'>
        <pose>0 0 0 0 -0 0</pose>
        <geometry>
          <mesh>
            <scale>1 1 1</scale>
            <uri>model://DRC_hubo/meshes/Body_LWY_col.STL</uri>
          </mesh>
        </geometry>
      </collision>

      <visual name='Body_LWY_visual'>
        <pose>0 0 0 0 -0 0</pose>
        <geometry>
          <mesh>
            <scale>1 1 1</scale>
            <uri>model://DRC_hubo/meshes/Body_LWY.STL</uri>
          </mesh>
        </geometry>
      </visual>

      <velocity_decay>
        <linear>0</linear>
        <angular>0</angular>
      </velocity_decay>
    </link>

    <joint name='LWY' type='revolute'>
      <child>Body_LWY</child>
      <parent>Body_LEB</parent>
      <axis>
        <xyz>0 0 1</xyz>
        <limit>
          <lower>-5</lower>
          <upper>5</upper>
          <effort>10000000</effort>
          <velocity>100</velocity>
        </limit>
        <dynamics>
          <damping>0.8</damping> <friction>50</friction>
        </dynamics>
      </axis>
    </joint>

    <link name='Body_LWP'>
      <pose>0 0.24202 -0.234 1.50408e-11 -6.8201e-08 -3.36547e-08</pose>
      <inertial>
        <pose>1.7e-05 0.011876 -0.003359 0 -0 0</pose>
        <mass>0.158865</mass>
        <inertia>
          <ixx>7.2e-04</ixx>
          <ixy>1e-06</ixy>
          <ixz>1e-06</ixz>
          <iyy>6.5e-04</iyy>
          <iyz>6e-05</iyz>
          <izz>6.5e-04</izz>
        </inertia>
      </inertial>

      <collision name='Body_LWP_collision'>
        <pose>0 0 0 0 -0 0</pose>
        <geometry>
          <mesh>
            <scale>1 1 1</scale>
            <uri>model://DRC_hubo/meshes/Body_LWP_col.STL</uri>
          </mesh>
        </geometry>
      </collision>

      <visual name='Body_LWP_visual'>
        <pose>0 0 0 0 -0 0</pose>
        <geometry>
          <mesh>
            <scale>1 1 1</scale>
            <uri>model://DRC_hubo/meshes/Body_LWP.STL</uri>
          </mesh>
        </geometry>
      </visual>

      <velocity_decay>
        <linear>0</linear>
        <angular>0</angular>
      </velocity_decay>
    </link>

    <joint name='LWP' type='revolute'>
      <child>Body_LWP</child>
      <parent>Body_LWY</parent>
      <axis>
        <xyz>0 1 0</xyz>
        <limit>
          <lower>-5</lower>
          <upper>5</upper>
          <effort>10000000</effort>
          <velocity>100</velocity>
        </limit>
        <dynamics>
          <damping>0.1</damping> <friction>0.2</friction>
        </dynamics>
      </axis>
    </joint>

    <link name='Body_LWFT'>
      <pose>1.00227e-06 0.24202 -0.26655 1.50659e-11 -6.82011e-08 -3.36547e-08</pose>
      <inertial>
        <pose>-1.2e-05 -3e-06 -0.017752 0 -0 0</pose>
        <mass>0.016659</mass>
        <inertia>
          <ixx>2e-05</ixx>
          <ixy>1e-06</ixy>
          <ixz>1e-06</ixz>
          <iyy>1.85e-05</iyy>
          <iyz>1e-06</iyz>
          <izz>3.33e-05</izz>
        </inertia>
      </inertial>

      <collision name='Body_LWFT_collision'>
        <pose>0 0 0 0 -0 0</pose>
        <geometry>
          <mesh>
            <scale>1 1 1</scale>
            <uri>model://DRC_hubo/meshes/Body_LWFT_col.STL</uri>
          </mesh>
        </geometry>
      </collision>

      <visual name='Body_LWFT_visual'>
        <pose>0 0 0 0 -0 0</pose>
        <geometry>
          <mesh>
            <scale>1 1 1</scale>
            <uri>model://DRC_hubo/meshes/Body_LWFT.STL</uri>
          </mesh>
        </geometry>
      </visual>

      <velocity_decay>
        <linear>0</linear>
        <angular>0</angular>
      </velocity_decay>

      <sensor name='FT_LWFT' type='contact'>
        <contact>
          <collision>Body_LWFT_collision</collision>
        </contact>
      </sensor>
    </link>

    <joint name='LWFT' type='prismatic'>
      <physics>
        <ode>
          <provide_feedback>true</provide_feedback>
        </ode>
      </physics>
      <child>Body_LWFT</child>
      <parent>Body_LWP</parent>
      <axis>
        <xyz>0 0 1</xyz>
        <limit>
          <lower>-0.0</lower>
          <upper>0.0</upper>
          <effort>10000000</effort>
          <velocity>1000000</velocity>
        </limit>
        <dynamics>
          <damping>1</damping> <friction>1</friction>
        </dynamics>
      </axis>
    </joint>

    <link name='Body_LF1'>
      <pose>-1.89999e-05 0.242055 -0.234 1.49855e-11 -6.82011e-08 2.04305e-07</pose>
      <inertial>
        <pose>0.00350179 0.00500094 -0.108683 0 -0 0</pose>
        <mass>0.894667</mass>
        <inertia>
          <ixx>0.00087045</ixx>
          <ixy>-1.448e-05</ixy>
          <ixz>-1.064e-05</ixz>
          <iyy>0.00103972</iyy>
          <iyz>-7.89e-06</iyz>
          <izz>0.00095329</izz>
        </inertia>
      </inertial>

      <collision name='Body_LF1_collision'>
        <pose>0 0 0 0 -0 0</pose>
        <geometry>
          <mesh>
            <scale>1 1 1</scale>
            <uri>model://DRC_hubo/meshes/Body_LF1_col.STL</uri>
          </mesh>
        </geometry>
      </collision>

      <visual name='Body_LF1_visual'>
        <pose>0 0 0 0 -0 0</pose>
        <geometry>
          <mesh>
            <scale>1 1 1</scale>
            <uri>model://DRC_hubo/meshes/Body_LF1.STL</uri>
          </mesh>
        </geometry>
      </visual>

      <velocity_decay>
        <linear>0</linear>
        <angular>0</angular>
      </velocity_decay>
    </link>

    <joint name='LWY2' type='revolute'>
      <child>Body_LF1</child>
      <parent>Body_LWFT</parent>
      <axis>
        <xyz>0 0 1</xyz>
        <limit>
          <lower>-5</lower>
          <upper>5</upper>
          <effort>10000000</effort>
          <velocity>100</velocity>
        </limit>
        <dynamics>
          <damping>0.1</damping> <friction>1</friction>
        </dynamics>
      </axis>
    </joint>

    <link name='Body_LF2_a1'>
      <pose>0.024981 0.218955 -0.38105 1.50476e-11 -6.93188e-08 2.04305e-07</pose>
      <inertial>
        <pose>-0.0228526 -0.00016373 -0.0095261 0 -0 0</pose>
        <mass>0.038683</mass>
        <inertia>
          <ixx>1.143e-04</ixx>
          <ixy>7e-06</ixy>
          <ixz>-6.53e-05</ixz>
          <iyy>2.17e-04</iyy>
          <iyz>-1e-05</iyz>
          <izz>1.314e-04</izz>
        </inertia>
      </inertial>

      <collision name='Body_LF2_a1_collision'>
        <pose>0 0 0 0 -0 0</pose>
        <geometry>
          <mesh>
            <scale>1 1 1</scale>
            <uri>model://DRC_hubo/meshes/Body_LF2_a1_col.STL</uri>
          </mesh>
        </geometry>
      </collision>

      <visual name='Body_LF2_a1_visual'>
        <pose>0 0 0 0 -0 0</pose>
        <geometry>
          <mesh>
            <scale>1 1 1</scale>
            <uri>model://DRC_hubo/meshes/Body_LF2_a1.STL</uri>
          </mesh>
        </geometry>
      </visual>

      <velocity_decay>
        <linear>0</linear>
        <angular>0</angular>
      </velocity_decay>
    </link>

    <joint name='LHAND_a1' type='revolute'>
      <child>Body_LF2_a1</child>
      <parent>Body_LF1</parent>
      <axis>
        <xyz>0 1 0</xyz>
        <limit>
          <lower>0</lower>
          <upper>1.4708</upper>
          <effort>10000000</effort>
          <velocity>100</velocity>
        </limit>
        <dynamics>
          <damping>0.0003</damping> <friction>0.1</friction>
        </dynamics>
      </axis>
    </joint>

    <link name='Body_LF2_a2'>
      <pose>0.063872 0.218905 -0.419941 2.12816e-11 0.7854 2.0432e-07</pose>
      <inertial>
        <pose>0.0183473 -5.73e-06 0.00742064 0 -0 0</pose>
        <mass>0.021949</mass>
        <inertia>
          <ixx>2.31e-05</ixx>
          <ixy>9e-06</ixy>
          <ixz>-4.6e-06</ixz>
          <iyy>7.09e-05</iyy>
          <iyz>-5e-06</iyz>
          <izz>6.69e-05</izz>
        </inertia>
      </inertial>

      <collision name='Body_LF2_a2_collision'>
        <pose>0 0 0 0 -0 0</pose>
        <geometry>
          <mesh>
            <scale>1 1 1</scale>
            <uri>model://DRC_hubo/meshes/Body_LF2_a2_col.STL</uri>
          </mesh>
        </geometry>
      </collision>

      <visual name='Body_LF2_a2_visual'>
        <pose>0 0 0 0 -0 0</pose>
        <geometry>
          <mesh>
            <scale>1 1 1</scale>
            <uri>model://DRC_hubo/meshes/Body_LF2_a2.STL</uri>
          </mesh>
        </geometry>
      </visual>

      <velocity_decay>
        <linear>0</linear>
        <angular>0</angular>
      </velocity_decay>
    </link>

    <joint name='LHAND_a2' type='revolute'>
      <child>Body_LF2_a2</child>
      <parent>Body_LF2_a1</parent>
      <axis>
        <xyz>0 1 0</xyz>
        <limit>
          <lower>0</lower>
          <upper>1.4708</upper>
          <effort>10000000</effort>
          <velocity>100</velocity>
        </limit>
        <dynamics>
          <damping>0.0003</damping> <friction>0.1</friction>
        </dynamics>
      </axis>
    </joint>

    <link name='Body_LF2_a3'>
      <pose>0.0921562 0.218855 -0.448225 2.12842e-11 0.7854 2.0432e-07</pose>
      <inertial>
        <pose>0.00112468 -3.724e-05 0.00681838 0 -0 0</pose>
        <mass>0.0115</mass>
        <inertia>
          <ixx>7.2e-05</ixx>
          <ixy>1e-06</ixy>
          <ixz>2.9e-05</ixz>
          <iyy>1.67e-05</iyy>
          <iyz>1e-06</iyz>
          <izz>1.84e-05</izz>
        </inertia>
      </inertial>

      <collision name='Body_LF2_a3_collision'>
        <pose>0 0 0 0 -0 0</pose>
        <geometry>
          <mesh>
            <scale>1 1 1</scale>
            <uri>model://DRC_hubo/meshes/Body_LF2_a3_col.STL</uri>
          </mesh>
        </geometry>
      </collision>

      <visual name='Body_LF2_a3_visual'>
        <pose>0 0 0 0 -0 0</pose>
        <geometry>
          <mesh>
            <scale>1 1 1</scale>
            <uri>model://DRC_hubo/meshes/Body_LF2_a3.STL</uri>
          </mesh>
        </geometry>
      </visual>

      <velocity_decay>
        <linear>0</linear>
        <angular>0</angular>
      </velocity_decay>
    </link>

    <joint name='LHAND_a3' type='revolute'>
      <child>Body_LF2_a3</child>
      <parent>Body_LF2_a2</parent>
      <axis>
        <xyz>0 1 0</xyz>
        <limit>
          <lower>0</lower>
          <upper>1.4708</upper>
          <effort>10000000</effort>
          <velocity>100</velocity>
        </limit>
        <dynamics>
          <damping>0.0003</damping> <friction>0.1</friction>
        </dynamics>
      </axis>
    </joint>

    <link name='Body_LF2_b1'>
      <pose>0.024981 0.265155 -0.38105 1.50453e-11 -6.93378e-08 2.04305e-07</pose>
      <inertial>
        <pose>-0.0228526 -0.00016373 -0.0095261 0 -0 0</pose>
        <mass>0.038683</mass>
        <inertia>
          <ixx>1.143e-04</ixx>
          <ixy>7e-06</ixy>
          <ixz>-6.53e-05</ixz>
          <iyy>2.17e-04</iyy>
          <iyz>-1e-05</iyz>
          <izz>1.314e-04</izz>
        </inertia>
      </inertial>

      <collision name='Body_LF2_b1_collision'>
        <pose>0 0 0 0 -0 0</pose>
        <geometry>
          <mesh>
            <scale>1 1 1</scale>
            <uri>model://DRC_hubo/meshes/Body_LF2_b1_col.STL</uri>
          </mesh>
        </geometry>
      </collision>

      <visual name='Body_LF2_b1_visual'>
        <pose>0 0 0 0 -0 0</pose>
        <geometry>
          <mesh>
            <scale>1 1 1</scale>
            <uri>model://DRC_hubo/meshes/Body_LF2_b1.STL</uri>
          </mesh>
        </geometry>
      </visual>

      <velocity_decay>
        <linear>0</linear>
        <angular>0</angular>
      </velocity_decay>
    </link>

    <joint name='LHAND_b1' type='revolute'>
      <child>Body_LF2_b1</child>
      <parent>Body_LF1</parent>
      <axis>
        <xyz>0 1 0</xyz>
        <limit>
          <lower>0</lower>
          <upper>1.4708</upper>
          <effort>10000000</effort>
          <velocity>100</velocity>
        </limit>
        <dynamics>
          <damping>0.0003</damping> <friction>0.1</friction>
        </dynamics>
      </axis>
    </joint>

    <link name='Body_LF2_b2'>
      <pose>0.063872 0.265155 -0.419941 2.12822e-11 0.7854 2.0432e-07</pose>
      <inertial>
        <pose>0.0183473 -5.73e-06 0.00742064 0 -0 0</pose>
        <mass>0.021949</mass>
        <inertia>
          <ixx>2.31e-05</ixx>
          <ixy>9e-06</ixy>
          <ixz>-4.6e-06</ixz>
          <iyy>7.09e-05</iyy>
          <iyz>-5e-06</iyz>
          <izz>6.69e-05</izz>
        </inertia>
      </inertial>

      <collision name='Body_LF2_b2_collision'>
        <pose>0 0 0 0 -0 0</pose>
        <geometry>
          <mesh>
            <scale>1 1 1</scale>
            <uri>model://DRC_hubo/meshes/Body_LF2_b2_col.STL</uri>
          </mesh>
        </geometry>
      </collision>

      <visual name='Body_LF2_b2_visual'>
        <pose>0 0 0 0 -0 0</pose>
        <geometry>
          <mesh>
            <scale>1 1 1</scale>
            <uri>model://DRC_hubo/meshes/Body_LF2_b2.STL</uri>
          </mesh>
        </geometry>
      </visual>

      <velocity_decay>
        <linear>0</linear>
        <angular>0</angular>
      </velocity_decay>
    </link>

    <joint name='LHAND_b2' type='revolute'>
      <child>Body_LF2_b2</child>
      <parent>Body_LF2_b1</parent>
      <axis>
        <xyz>0 1 0</xyz>
        <limit>
          <lower>0</lower>
          <upper>1.4708</upper>
          <effort>10000000</effort>
          <velocity>100</velocity>
        </limit>
        <dynamics>
          <damping>0.0003</damping> <friction>0.1</friction>
        </dynamics>
      </axis>
    </joint>

    <link name='Body_LF2_b3'>
      <pose>0.0921562 0.265255 -0.448225 2.12803e-11 0.7854 2.0432e-07</pose>
      <inertial>
        <pose>0.00112468 -3.724e-05 0.00681838 0 -0 0</pose>
        <mass>0.0115</mass>
        <inertia>
          <ixx>7.2e-05</ixx>
          <ixy>1e-06</ixy>
          <ixz>2.9e-05</ixz>
          <iyy>1.67e-05</iyy>
          <iyz>1e-06</iyz>
          <izz>1.84e-05</izz>
        </inertia>
      </inertial>

      <collision name='Body_LF2_b3_collision'>
        <pose>0 0 0 0 -0 0</pose>
        <geometry>
          <mesh>
            <scale>1 1 1</scale>
            <uri>model://DRC_hubo/meshes/Body_LF2_b3_col.STL</uri>
          </mesh>
        </geometry>
      </collision>

      <visual name='Body_LF2_b3_visual'>
        <pose>0 0 0 0 -0 0</pose>
        <geometry>
          <mesh>
            <scale>1 1 1</scale>
            <uri>model://DRC_hubo/meshes/Body_LF2_b3.STL</uri>
          </mesh>
        </geometry>
      </visual>

      <velocity_decay>
        <linear>0</linear>
        <angular>0</angular>
      </velocity_decay>
    </link>

    <joint name='LHAND_b3' type='revolute'>
      <child>Body_LF2_b3</child>
      <parent>Body_LF2_b2</parent>
      <axis>
        <xyz>0 1 0</xyz>
        <limit>
          <lower>0</lower>
          <upper>1.4708</upper>
          <effort>10000000</effort>
          <velocity>100</velocity>
        </limit>
        <dynamics>
          <damping>0.0003</damping> <friction>0.1</friction>
        </dynamics>
      </axis>
    </joint>

    <link name='Body_LF2_c1'>
      <pose>-0.025019 0.242055 -0.38105 1.50508e-11 -6.9339e-08 2.04305e-07</pose>
      <inertial>
        <pose>-0.0228526 0.00016373 -0.0095261 0 -0 0</pose>
        <mass>0.038683</mass>
        <inertia>
          <ixx>1.143e-04</ixx>
          <ixy>7e-06</ixy>
          <ixz>-6.53e-05</ixz>
          <iyy>2.17e-04</iyy>
          <iyz>-1e-05</iyz>
          <izz>1.314e-04</izz>
        </inertia>
      </inertial>

      <collision name='Body_LF2_c1_collision'>
        <pose>0 0 0 0 -0 0</pose>
        <geometry>
          <mesh>
            <scale>1 1 1</scale>
            <uri>model://DRC_hubo/meshes/Body_LF2_c1_col.STL</uri>
          </mesh>
        </geometry>
      </collision>

      <visual name='Body_LF2_c1_visual'>
        <pose>0 0 0 0 -0 0</pose>
        <geometry>
          <mesh>
            <scale>1 1 1</scale>
            <uri>model://DRC_hubo/meshes/Body_LF2_c1.STL</uri>
          </mesh>
        </geometry>
      </visual>

      <velocity_decay>
        <linear>0</linear>
        <angular>0</angular>
      </velocity_decay>
    </link>

    <joint name='LHAND_c1' type='revolute'>
      <child>Body_LF2_c1</child>
      <parent>Body_LF1</parent>
      <axis>
        <xyz>0 -1 0</xyz>
        <limit>
          <lower>0</lower>
          <upper>1.4708</upper>
          <effort>10000000</effort>
          <velocity>100</velocity>
        </limit>
        <dynamics>
          <damping>0.0003</damping> <friction>0.1</friction>
        </dynamics>
      </axis>
    </joint>

    <link name='Body_LF2_c2'>
      <pose>-0.06391 0.242105 -0.419941 2.12863e-11 -0.7854 2.0429e-07</pose>
      <inertial>
        <pose>-0.0183473 5.73e-06 0.00742064 0 -0 0</pose>
        <mass>0.021949</mass>
        <inertia>
          <ixx>2.31e-05</ixx>
          <ixy>9e-06</ixy>
          <ixz>-4.6e-06</ixz>
          <iyy>7.09e-05</iyy>
          <iyz>-5e-06</iyz>
          <izz>6.69e-05</izz>
        </inertia>
      </inertial>

      <collision name='Body_LF2_c2_collision'>
        <pose>0 0 0 0 -0 0</pose>
        <geometry>
          <mesh>
            <scale>1 1 1</scale>
            <uri>model://DRC_hubo/meshes/Body_LF2_c2_col.STL</uri>
          </mesh>
        </geometry>
      </collision>

      <visual name='Body_LF2_c2_visual'>
        <pose>0 0 0 0 -0 0</pose>
        <geometry>
          <mesh>
            <scale>1 1 1</scale>
            <uri>model://DRC_hubo/meshes/Body_LF2_c2.STL</uri>
          </mesh>
        </geometry>
      </visual>

      <velocity_decay>
        <linear>0</linear>
        <angular>0</angular>
      </velocity_decay>
    </link>

    <joint name='LHAND_c2' type='revolute'>
      <child>Body_LF2_c2</child>
      <parent>Body_LF2_c1</parent>
      <axis>
        <xyz>0 -1 0</xyz>
        <limit>
          <lower>0</lower>
          <upper>1.4708</upper>
          <effort>10000000</effort>
          <velocity>100</velocity>
        </limit>
        <dynamics>
          <damping>0.0003</damping> <friction>0.1</friction>
        </dynamics>
      </axis>
    </joint>

    <link name='Body_LF2_c3'>
      <pose>-0.0921942 0.242155 -0.448225 2.12858e-11 -0.7854 2.0429e-07</pose>
      <inertial>
        <pose>-0.00112468 3.724e-05 0.00681838 0 -0 0</pose>
        <mass>0.0115</mass>
        <inertia>
          <ixx>7.2e-05</ixx>
          <ixy>1e-06</ixy>
          <ixz>2.9e-05</ixz>
          <iyy>1.67e-05</iyy>
          <iyz>1e-06</iyz>
          <izz>1.84e-05</izz>
        </inertia>
      </inertial>

      <collision name='Body_LF2_c3_collision'>
        <pose>0 0 0 0 -0 0</pose>
        <geometry>
          <mesh>
            <scale>1 1 1</scale>
            <uri>model://DRC_hubo/meshes/Body_LF2_c3_col.STL</uri>
          </mesh>
        </geometry>
      </collision>

      <visual name='Body_LF2_c3_visual'>
        <pose>0 0 0 0 -0 0</pose>
        <geometry>
          <mesh>
            <scale>1 1 1</scale>
            <uri>model://DRC_hubo/meshes/Body_LF2_c3.STL</uri>
          </mesh>
        </geometry>
      </visual>

      <velocity_decay>
        <linear>0</linear>
        <angular>0</angular>
      </velocity_decay>
    </link>

    <joint name='LHAND_c3' type='revolute'>
      <child>Body_LF2_c3</child>
      <parent>Body_LF2_c2</parent>
      <axis>
        <xyz>0 -1 0</xyz>
        <limit>
          <lower>0</lower>
          <upper>1.4708</upper>
        </limit>
        <dynamics>
          <damping>0.0003</damping> <friction>0.1</friction>
        </dynamics>
      </axis>
    </joint>

    <link name='Body_RSP'>
      <pose>0 -0.2419 0.456 -5.1466e-08 5.8329e-08 -3.4194e-16</pose>
      <inertial>
        <pose>0.015596 0.052409 0 0 -0 0</pose>
        <mass>1.6</mass>
        <inertia>
          <ixx>0.005195</ixx>
          <ixy>-0.001333</ixy>
          <ixz>1e-08</ixz>
          <iyy>0.004409</iyy>
          <iyz>-1e-08</iyz>
          <izz>0.007234</izz>
        </inertia>
      </inertial>

      <collision name='Body_RSP_collision'>
        <pose>0 0 0 0 -0 0</pose>
        <geometry>
          <mesh>
            <scale>1 1 1</scale>
            <uri>model://DRC_hubo/meshes/Body_RSP_col.STL</uri>
          </mesh>
        </geometry>
      </collision>

      <visual name='Body_RSP_visual'>
        <pose>0 0 0 0 -0 0</pose>
        <geometry>
          <mesh>
            <scale>1 1 1</scale>
            <uri>model://DRC_hubo/meshes/Body_RSP.STL</uri>
          </mesh>
        </geometry>
      </visual>

      <velocity_decay>
        <linear>0</linear>
        <angular>0</angular>
      </velocity_decay>
    </link>

    <joint name='RSP' type='revolute'>
      <child>Body_RSP</child>
      <parent>Body_TORSO</parent>
      <axis>
        <xyz>0 1 0</xyz>
        <limit>
          <lower>-5</lower>
          <upper>5</upper>
          <effort>10000000</effort>
          <velocity>100</velocity>
        </limit>
        <dynamics>
          <damping>15</damping> <friction>2</friction>
        </dynamics>
      </axis>
    </joint>

    <link name='Body_RSR'>
      <pose>0 -0.2419 0.456 -2e-12 5.8329e-08 -1.77024e-12</pose>
      <inertial>
        <pose>-0.003104 -0.000106 -0.013013 0 -0 0</pose>
        <mass>1.427</mass>
        <inertia>
          <ixx>0.003163</ixx>
          <ixy>-6e-06</ixy>
          <ixz>-0.000211</ixz>
          <iyy>0.003689</iyy>
          <iyz>-1e-08</iyz>
          <izz>0.001909</izz>
        </inertia>
      </inertial>

      <collision name='Body_RSR_collision'>
        <pose>0 0 0 0 -0 0</pose>
        <geometry>
          <mesh>
            <scale>1 1 1</scale>
            <uri>model://DRC_hubo/meshes/Body_RSR_col.STL</uri>
          </mesh>
        </geometry>
      </collision>

      <visual name='Body_RSR_visual'>
        <pose>0 0 0 0 -0 0</pose>
        <geometry>
          <mesh>
            <scale>1 1 1</scale>
            <uri>model://DRC_hubo/meshes/Body_RSR.STL</uri>
          </mesh>
        </geometry>
      </visual>

      <velocity_decay>
        <linear>0</linear>
        <angular>0</angular>
      </velocity_decay>
    </link>

    <joint name='RSR' type='revolute'>
      <child>Body_RSR</child>
      <parent>Body_RSP</parent>
      <axis>
        <xyz>1 0 0</xyz>
        <limit>
          <lower>-5.14</lower>
          <upper>5.14</upper>
          <effort>10000000</effort>
          <velocity>100</velocity>
        </limit>
        <dynamics>
          <damping>15</damping> <friction>2</friction>
        </dynamics>
      </axis>
    </joint>

    <link name='Body_RSY'>
      <pose>0 -0.2419 0.456 -2.10147e-12 5.8329e-08 -1.7372e-06</pose>
      <inertial>
        <pose>0.00429109 -0.00371065 -0.238921 0 -0 0</pose>
        <mass>2.35838</mass>
        <inertia>
          <ixx>0.024139</ixx>
          <ixy>-0.000334</ixy>
          <ixz>-0.003948</ixz>
          <iyy>0.024861</iyy>
          <iyz>0.001103</iyz>
          <izz>0.003447</izz>
        </inertia>
      </inertial>

      <collision name='Body_RSY_collision'>
        <pose>0 0 0 0 -0 0</pose>
        <geometry>
          <mesh>
            <scale>1 1 1</scale>
            <uri>model://DRC_hubo/meshes/Body_RSY_col.STL</uri>
          </mesh>
        </geometry>
      </collision>

      <visual name='Body_RSY_visual'>
        <pose>0 0 0 0 -0 0</pose>
        <geometry>
          <mesh>
            <scale>1 1 1</scale>
            <uri>model://DRC_hubo/meshes/Body_RSY.STL</uri>
          </mesh>
        </geometry>
      </visual>

      <velocity_decay>
        <linear>0</linear>
        <angular>0</angular>
      </velocity_decay>
    </link>

    <joint name='RSY' type='revolute'>
      <child>Body_RSY</child>
      <parent>Body_RSR</parent>
      <axis>
        <xyz>0 0 1</xyz>
        <limit>
          <lower>-5</lower>
          <upper>5</upper>
          <effort>10000000</effort>
          <velocity>100</velocity>
        </limit>
        <dynamics>
          <damping>5</damping> <friction>2</friction>
        </dynamics>
      </axis>
    </joint>

    <link name='Body_REB'>
      <pose>0.035001 -0.24192 0.106 -2.10196e-12 -0.000489509 -1.7372e-06</pose>
      <inertial>
        <pose>-0.019775 -0.004924 -0.041836 0 -0 0</pose>
        <mass>0.409464</mass>
        <inertia>
          <ixx>0.001031</ixx>
          <ixy>-4e-05</ixy>
          <ixz>0.000277</ixz>
          <iyy>0.001163</iyy>
          <iyz>-8.5e-05</iyz>
          <izz>0.00056</izz>
        </inertia>
      </inertial>

      <collision name='Body_REB_collision'>
        <pose>0 0 0 0 -0 0</pose>
        <geometry>
          <mesh>
            <scale>1 1 1</scale>
            <uri>model://DRC_hubo/meshes/Body_REB_col.STL</uri>
          </mesh>
        </geometry>
      </collision>

      <visual name='Body_REB_visual'>
        <pose>0 0 0 0 -0 0</pose>
        <geometry>
          <mesh>
            <scale>1 1 1</scale>
            <uri>model://DRC_hubo/meshes/Body_REB.STL</uri>
          </mesh>
        </geometry>
      </visual>

      <velocity_decay>
        <linear>0</linear>
        <angular>0</angular>
      </velocity_decay>
    </link>

    <joint name='REB' type='revolute'>
      <child>Body_REB</child>
      <parent>Body_RSY</parent>
      <axis>
        <xyz>0 1 0</xyz>
        <limit>
          <lower>-5</lower>
          <upper>5</upper>
          <effort>10000000</effort>
          <velocity>100</velocity>
        </limit>
        <dynamics>
          <damping>8</damping> <friction>2</friction>
        </dynamics>
      </axis>
    </joint>

    <link name='Body_RWY'>
      <pose>7.22675e-07 -0.24192 -0.234 -3.41098e-13 5.83291e-08 -3.44439e-08</pose>
      <inertial>
        <pose>5.4e-05 -0.001779 0.134651 0 -0 0</pose>
        <mass>1.47</mass>
        <inertia>
          <ixx>0.01302</ixx>
          <ixy>1e-05</ixy>
          <ixz>4e-05</ixz>
          <iyy>0.012803</iyy>
          <iyz>0.000388</iyz>
          <izz>0.000862</izz>
        </inertia>
      </inertial>

      <collision name='Body_RWY_collision'>
        <pose>0 0 0 0 -0 0</pose>
        <geometry>
          <mesh>
            <scale>1 1 1</scale>
            <uri>model://DRC_hubo/meshes/Body_RWY_col.STL</uri>
          </mesh>
        </geometry>
      </collision>

      <visual name='Body_RWY_visual'>
        <pose>0 0 0 0 -0 0</pose>
        <geometry>
          <mesh>
            <scale>1 1 1</scale>
            <uri>model://DRC_hubo/meshes/Body_RWY.STL</uri>
          </mesh>
        </geometry>
      </visual>

      <velocity_decay>
        <linear>0</linear>
        <angular>0</angular>
      </velocity_decay>
    </link>

    <joint name='RWY' type='revolute'>
      <child>Body_RWY</child>
      <parent>Body_REB</parent>
      <axis>
        <xyz>0 0 1</xyz>
        <limit>
          <lower>-5</lower>
          <upper>5</upper>
          <effort>10000000</effort>
          <velocity>1000</velocity>
        </limit>
        <dynamics>
          <damping>0.8</damping> <friction>50</friction>
        </dynamics>
      </axis>
    </joint>

    <link name='Body_RWP'>
      <pose>7.22675e-07 -0.24192 -0.234 -3.43106e-13 1.74609e-07 -3.44439e-08</pose>
      <inertial>
        <pose>1.7e-05 -0.011876 -0.003359 0 -0 0</pose>
        <mass>0.158865</mass>
        <inertia>
          <ixx>7.2e-04</ixx>
          <ixy>-1e-06</ixy>
          <ixz>1e-06</ixz>
          <iyy>6.5e-04</iyy>
          <iyz>-6e-05</iyz>
          <izz>6.5e-04</izz>
        </inertia>
      </inertial>

      <collision name='Body_RWP_collision'>
        <pose>0 0 0 0 -0 0</pose>
        <geometry>
          <mesh>
            <scale>1 1 1</scale>
            <uri>model://DRC_hubo/meshes/Body_RWP_col.STL</uri>
          </mesh>
        </geometry>
      </collision>

      <visual name='Body_RWP_visual'>
        <pose>0 0 0 0 -0 0</pose>
        <geometry>
          <mesh>
            <scale>1 1 1</scale>
            <uri>model://DRC_hubo/meshes/Body_RWP.STL</uri>
          </mesh>
        </geometry>
      </visual>

      <velocity_decay>
        <linear>0</linear>
        <angular>0</angular>
      </velocity_decay>
    </link>

    <joint name='RWP' type='revolute'>
      <child>Body_RWP</child>
      <parent>Body_RWY</parent>
      <axis>
        <xyz>0 1 0</xyz>
        <limit>
          <lower>-5</lower>
          <upper>5</upper>
          <effort>10000000</effort>
          <velocity>100</velocity>
        </limit>
        <dynamics>
          <damping>0.1</damping> <friction>0.2</friction>
        </dynamics>
      </axis>
    </joint>

    <link name='Body_RWFT'>
      <pose>7.16992e-07 -0.24192 -0.26655 -3.65937e-13 1.74609e-07 -3.44439e-08</pose>
      <inertial>
        <pose>-1.2e-05 3e-06 -0.017752 0 -0 0</pose>
        <mass>0.016659</mass>
        <inertia>
          <ixx>2e-05</ixx>
          <ixy>-1e-06</ixy>
          <ixz>1e-06</ixz>
          <iyy>1.85e-05</iyy>
          <iyz>-1e-06</iyz>
          <izz>3.33e-05</izz>
        </inertia>
      </inertial>

      <collision name='Body_RWFT_collision'>
        <pose>0 0 0 0 -0 0</pose>
        <geometry>
          <mesh>
            <scale>1 1 1</scale>
            <uri>model://DRC_hubo/meshes/Body_RWFT_col.STL</uri>
          </mesh>
        </geometry>
      </collision>

      <visual name='Body_RWFT_visual'>
        <pose>0 0 0 0 -0 0</pose>
        <geometry>
          <mesh>
            <scale>1 1 1</scale>
            <uri>model://DRC_hubo/meshes/Body_RWFT.STL</uri>
          </mesh>
        </geometry>
      </visual>

      <velocity_decay>
        <linear>0</linear>
        <angular>0</angular>
      </velocity_decay>

      <sensor name='FT_RWFT' type='contact'>
        <contact>
          <collision>Body_RWFT_collision</collision>
        </contact>
      </sensor>
    </link>

    <joint name='RWFT' type='prismatic'>
      <physics>
        <ode>
          <provide_feedback>true</provide_feedback>
        </ode>
      </physics>
      <child>Body_RWFT</child>
      <parent>Body_RWP</parent>
      <axis>
        <xyz>0 0 1</xyz>
        <limit>
          <lower>-0</lower>
          <upper>0</upper>
          <effort>10000000</effort>
          <velocity>100</velocity>
        </limit>
        <dynamics>
          <damping>1</damping> <friction>1</friction>
        </dynamics>
      </axis>
    </joint>

    <link name='Body_RF1'>
      <pose>-1.92773e-05 -0.241955 -0.234 -3.56316e-13 1.74609e-07 7.24513e-09</pose>
      <inertial>
        <pose>0.00350179 -0.00500094 -0.108683 0 -0 0</pose>
        <mass>0.894667</mass>
        <inertia>
          <ixx>0.00087045</ixx>
          <ixy>1.448e-05</ixy>
          <ixz>-1.064e-05</ixz>
          <iyy>0.00103972</iyy>
          <iyz>7.89e-06</iyz>
          <izz>0.00095329</izz>
        </inertia>
      </inertial>

      <collision name='Body_RF1_collision'>
        <pose>0 0 0 0 -0 0</pose>
        <geometry>
          <mesh>
            <scale>1 1 1</scale>
            <uri>model://DRC_hubo/meshes/Body_RF1_col.STL</uri>
          </mesh>
        </geometry>
      </collision>

      <visual name='Body_RF1_visual'>
        <pose>0 0 0 0 -0 0</pose>
        <geometry>
          <mesh>
            <scale>1 1 1</scale>
            <uri>model://DRC_hubo/meshes/Body_RF1.STL</uri>
          </mesh>
        </geometry>
      </visual>

      <velocity_decay>
        <linear>0</linear>
        <angular>0</angular>
      </velocity_decay>
    </link>

    <joint name='RWY2' type='revolute'>
      <child>Body_RF1</child>
      <parent>Body_RWFT</parent>
      <axis>
        <xyz>0 0 1</xyz>
        <limit>
          <lower>-5</lower>
          <upper>5</upper>
          <effort>10000000</effort>
          <velocity>100</velocity>
        </limit>
        <dynamics>
          <damping>0.1</damping> <friction>1</friction>
        </dynamics>
      </axis>
    </joint>

    <link name='Body_RF2_a1'>
      <pose>0.0249807 -0.265055 -0.38105 -3.55927e-13 1.51991e-08 7.24513e-09</pose>
      <inertial>
        <pose>-0.0228526 -0.00016373 -0.0095261 0 -0 0</pose>
        <mass>0.038683</mass>
        <inertia>
          <ixx>1.143e-04</ixx>
          <ixy>7e-06</ixy>
          <ixz>-6.53e-05</ixz>
          <iyy>2.17e-04</iyy>
          <iyz>-1e-05</iyz>
          <izz>1.314e-04</izz>
        </inertia>
      </inertial>

      <collision name='Body_RF2_a1_collision'>
        <pose>0 0 0 0 -0 0</pose>
        <geometry>
          <mesh>
            <scale>1 1 1</scale>
            <uri>model://DRC_hubo/meshes/Body_RF2_a1_col.STL</uri>
          </mesh>
        </geometry>
        <surface>
          <friction>
            <ode>
              <mu>1.0</mu>
              <mu2>1.0</mu2>
            </ode>
          </friction>
          <contact>
            <ode>
              <kp>10000000.0</kp>
              <kd>1.0</kd>
              <min_depth>0.001</min_depth>
              <max_vel>0.1</max_vel>
            </ode>
          </contact>
        </surface>
      </collision>

      <visual name='Body_RF2_a1_visual'>
        <pose>0 0 0 0 -0 0</pose>
        <geometry>
          <mesh>
            <scale>1 1 1</scale>
            <uri>model://DRC_hubo/meshes/Body_RF2_a1.STL</uri>
          </mesh>
        </geometry>
      </visual>

      <velocity_decay>
        <linear>0</linear>
        <angular>0</angular>
      </velocity_decay>
    </link>

    <joint name='RHAND_a1' type='revolute'>
      <child>Body_RF2_a1</child>
      <parent>Body_RF1</parent>
      <axis>
        <xyz>0 1 0</xyz>
        <limit>
          <lower>0</lower>
          <upper>1.4708</upper>
          <effort>10000000</effort>
          <velocity>100</velocity>
        </limit>
        <dynamics>
          <damping>0.0003</damping> <friction>0.1</friction>
        </dynamics>
      </axis>
    </joint>

    <link name='Body_RF2_a2'>
      <pose>0.0638717 -0.265105 -0.419941 -4.97149e-13 0.7854 7.24479e-09</pose>
      <inertial>
        <pose>0.0183473 -5.73e-06 0.00742064 0 -0 0</pose>
        <mass>0.021949</mass>
        <inertia>
          <ixx>2.31e-05</ixx>
          <ixy>9e-06</ixy>
          <ixz>-4.6e-06</ixz>
          <iyy>7.09e-05</iyy>
          <iyz>-5e-06</iyz>
          <izz>6.69e-05</izz>
        </inertia>
      </inertial>

      <collision name='Body_RF2_a2_collision'>
        <pose>0 0 0 0 -0 0</pose>
        <geometry>
          <mesh>
            <scale>1 1 1</scale>
            <uri>model://DRC_hubo/meshes/Body_RF2_a2_col.STL</uri>
          </mesh>
        </geometry>
        <surface>
          <friction>
            <ode>
              <mu>1.0</mu>
              <mu2>1.0</mu2>
            </ode>
          </friction>
          <contact>
            <ode>
              <kp>10000000.0</kp>
              <kd>1.0</kd>
              <min_depth>0.001</min_depth>
              <max_vel>0.1</max_vel>
            </ode>
          </contact>
        </surface>
      </collision>

      <visual name='Body_RF2_a2_visual'>
        <pose>0 0 0 0 -0 0</pose>
        <geometry>
          <mesh>
            <scale>1 1 1</scale>
            <uri>model://DRC_hubo/meshes/Body_RF2_a2.STL</uri>
          </mesh>
        </geometry>
      </visual>

      <velocity_decay>
        <linear>0</linear>
        <angular>0</angular>
      </velocity_decay>
    </link>

    <joint name='RHAND_a2' type='revolute'>
      <child>Body_RF2_a2</child>
      <parent>Body_RF2_a1</parent>
      <axis>
        <xyz>0 1 0</xyz>
        <limit>
          <lower>0</lower>
          <upper>1.4708</upper>
          <effort>10000000</effort>
          <velocity>100</velocity>
        </limit>
        <dynamics>
          <damping>0.0003</damping> <friction>0.1</friction>
        </dynamics>
      </axis>
    </joint>

    <link name='Body_RF2_a3'>
      <pose>0.0921559 -0.265155 -0.448225 -5.00188e-13 0.7854 7.24478e-09</pose>
      <inertial>
        <pose>0.00112468 -3.724e-05 0.00681838 0 -0 0</pose>
        <mass>0.0115</mass>
        <inertia>
          <ixx>7.2e-05</ixx>
          <ixy>1e-06</ixy>
          <ixz>2.9e-05</ixz>
          <iyy>1.67e-05</iyy>
          <iyz>1e-06</iyz>
          <izz>1.84e-05</izz>
        </inertia>
      </inertial>

      <collision name='Body_RF2_a3_collision'>
        <pose>0 0 0 0 -0 0</pose>
        <geometry>
          <mesh>
            <scale>1 1 1</scale>
            <uri>model://DRC_hubo/meshes/Body_RF2_a3_col.STL</uri>
          </mesh>
        </geometry>
        <surface>
          <friction>
            <ode>
              <mu>1.0</mu>
              <mu2>1.0</mu2>
            </ode>
          </friction>
          <contact>
            <ode>
              <kp>10000000.0</kp>
              <kd>1.0</kd>
              <min_depth>0.001</min_depth>
              <max_vel>0.1</max_vel>
            </ode>
          </contact>
        </surface>
      </collision>

      <visual name='Body_RF2_a3_visual'>
        <pose>0 0 0 0 -0 0</pose>
        <geometry>
          <mesh>
            <scale>1 1 1</scale>
            <uri>model://DRC_hubo/meshes/Body_RF2_a3.STL</uri>
          </mesh>
        </geometry>
      </visual>

      <velocity_decay>
        <linear>0</linear>
        <angular>0</angular>
      </velocity_decay>
    </link>

    <joint name='RHAND_a3' type='revolute'>
      <child>Body_RF2_a3</child>
      <parent>Body_RF2_a2</parent>
      <axis>
        <xyz>0 1 0</xyz>
        <limit>
          <lower>0</lower>
          <upper>1.4708</upper>
          <effort>10000000</effort>
          <velocity>100</velocity>
        </limit>
        <dynamics>
          <damping>0.0003</damping> <friction>0.1</friction>
        </dynamics>
      </axis>
    </joint>

    <link name='Body_RF2_b1'>
      <pose>0.0249807 -0.218655 -0.38105 -3.55892e-13 1.51991e-08 7.24514e-09</pose>
      <inertial>
        <pose>-0.0228526 -0.00016373 -0.0095261 0 -0 0</pose>
        <mass>0.038683</mass>
        <inertia>
          <ixx>1.143e-04</ixx>
          <ixy>7e-06</ixy>
          <ixz>-6.53e-05</ixz>
          <iyy>2.17e-04</iyy>
          <iyz>-1e-05</iyz>
          <izz>1.314e-04</izz>
        </inertia>>
      </inertial>

      <collision name='Body_RF2_b1_collision'>
        <pose>0 0 0 0 -0 0</pose>
        <geometry>
          <mesh>
            <scale>1 1 1</scale>
            <uri>model://DRC_hubo/meshes/Body_RF2_b1_col.STL</uri>
          </mesh>
        </geometry>
        <surface>
          <friction>
            <ode>
              <mu>1.0</mu>
              <mu2>1.0</mu2>
            </ode>
          </friction>
          <contact>
            <ode>
              <kp>10000000.0</kp>
              <kd>1.0</kd>
              <min_depth>0.001</min_depth>
              <max_vel>0.1</max_vel>
            </ode>
          </contact>
        </surface>
      </collision>

      <visual name='Body_RF2_b1_visual'>
        <pose>0 0 0 0 -0 0</pose>
        <geometry>
          <mesh>
            <scale>1 1 1</scale>
            <uri>model://DRC_hubo/meshes/Body_RF2_b1.STL</uri>
          </mesh>
        </geometry>
      </visual>

      <velocity_decay>
        <linear>0</linear>
        <angular>0</angular>
      </velocity_decay>
    </link>

    <joint name='RHAND_b1' type='revolute'>
      <child>Body_RF2_b1</child>
      <parent>Body_RF1</parent>
      <axis>
        <xyz>0 1 0</xyz>
        <limit>
          <lower>0</lower>
          <upper>1.4708</upper>
          <effort>10000000</effort>
          <velocity>100</velocity>
        </limit>
        <dynamics>
          <damping>0.0003</damping> <friction>0.1</friction>
        </dynamics>
      </axis>
    </joint>

    <link name='Body_RF2_b2'>
      <pose>0.0638717 -0.218605 -0.419941 -4.99875e-13 0.7854 7.24478e-09</pose>
      <inertial>
        <pose>0.0183473 -5.73e-06 0.00742064 0 -0 0</pose>
        <mass>0.021949</mass>
        <inertia>
          <ixx>2.31e-05</ixx>
          <ixy>9e-06</ixy>
          <ixz>-4.6e-06</ixz>
          <iyy>7.09e-05</iyy>
          <iyz>-5e-06</iyz>
          <izz>6.69e-05</izz>
        </inertia>
      </inertial>

      <collision name='Body_RF2_b2_collision'>
        <pose>0 0 0 0 -0 0</pose>
        <geometry>
          <mesh>
            <scale>1 1 1</scale>
            <uri>model://DRC_hubo/meshes/Body_RF2_b2_col.STL</uri>
          </mesh>
        </geometry>
        <surface>
          <friction>
            <ode>
              <mu>1.0</mu>
              <mu2>1.0</mu2>
            </ode>
          </friction>
          <contact>
            <ode>
              <kp>10000000.0</kp>
              <kd>1.0</kd>
              <min_depth>0.001</min_depth>
              <max_vel>0.1</max_vel>
            </ode>
          </contact>
        </surface>
      </collision>

      <visual name='Body_RF2_b2_visual'>
        <pose>0 0 0 0 -0 0</pose>
        <geometry>
          <mesh>
            <scale>1 1 1</scale>
            <uri>model://DRC_hubo/meshes/Body_RF2_b2.STL</uri>
          </mesh>
        </geometry>
      </visual>

      <velocity_decay>
        <linear>0</linear>
        <angular>0</angular>
      </velocity_decay>
    </link>

    <joint name='RHAND_b2' type='revolute'>
      <child>Body_RF2_b2</child>
      <parent>Body_RF2_b1</parent>
      <axis>
        <xyz>0 1 0</xyz>
        <limit>
          <lower>0</lower>
          <upper>1.4708</upper>
          <effort>10000000</effort>
          <velocity>100</velocity>
        </limit>
        <dynamics>
          <damping>0.0003</damping> <friction>0.1</friction>
        </dynamics>
      </axis>
    </joint>

    <link name='Body_RF2_b3'>
      <pose>0.0921559 -0.218555 -0.448225 -5.00332e-13 0.7854 7.24478e-09</pose>
      <inertial>
        <pose>0.00112468 -3.724e-05 0.00681838 0 -0 0</pose>
        <mass>0.0115</mass>
        <inertia>
          <ixx>7.2e-05</ixx>
          <ixy>1e-06</ixy>
          <ixz>2.9e-05</ixz>
          <iyy>1.67e-05</iyy>
          <iyz>1e-06</iyz>
          <izz>1.84e-05</izz>
        </inertia>
      </inertial>

      <collision name='Body_RF2_b3_collision'>
        <pose>0 0 0 0 -0 0</pose>
        <geometry>
          <mesh>
            <scale>1 1 1</scale>
            <uri>model://DRC_hubo/meshes/Body_RF2_b3_col.STL</uri>
          </mesh>
        </geometry>
        <surface>
          <friction>
            <ode>
              <mu>1.0</mu>
              <mu2>1.0</mu2>
            </ode>
          </friction>
          <contact>
            <ode>
              <kp>10000000.0</kp>
              <kd>1.0</kd>
              <min_depth>0.001</min_depth>
              <max_vel>0.1</max_vel>
            </ode>
          </contact>
        </surface>
      </collision>

      <visual name='Body_RF2_b3_visual'>
        <pose>0 0 0 0 -0 0</pose>
        <geometry>
          <mesh>
            <scale>1 1 1</scale>
            <uri>model://DRC_hubo/meshes/Body_RF2_b3.STL</uri>
          </mesh>
        </geometry>
      </visual>

      <velocity_decay>
        <linear>0</linear>
        <angular>0</angular>
      </velocity_decay>
    </link>

    <joint name='RHAND_b3' type='revolute'>
      <child>Body_RF2_b3</child>
      <parent>Body_RF2_b2</parent>
      <axis>
        <xyz>0 1 0</xyz>
        <limit>
          <lower>0</lower>
          <upper>1.4708</upper>
          <effort>10000000</effort>
          <velocity>100</velocity>
        </limit>
        <dynamics>
          <damping>0.0003</damping> <friction>0.1</friction>
        </dynamics>
      </axis>
    </joint>

    <link name='Body_RF2_c1'>
      <pose>-0.0250193 -0.241755 -0.38105 -3.48932e-13 -2.56409e-08 7.24514e-09</pose>
      <inertial>
        <pose>-0.0228526 0.00016373 -0.0095261 0 -0 0</pose>
        <mass>0.038683</mass>
        <inertia>
          <ixx>1.143e-04</ixx>
          <ixy>7e-06</ixy>
          <ixz>-6.53e-05</ixz>
          <iyy>2.17e-04</iyy>
          <iyz>-1e-05</iyz>
          <izz>1.314e-04</izz>
        </inertia>
      </inertial>

      <collision name='Body_RF2_c1_collision'>
        <pose>0 0 0 0 -0 0</pose>
        <geometry>
          <mesh>
            <scale>1 1 1</scale>
            <uri>model://DRC_hubo/meshes/Body_RF2_c1_col.STL</uri>
          </mesh>
        </geometry>
        <surface>
          <friction>
            <ode>
              <mu>1.0</mu>
              <mu2>1.0</mu2>
            </ode>
          </friction>
          <contact>
            <ode>
              <kp>10000000.0</kp>
              <kd>1.0</kd>
              <min_depth>0.001</min_depth>
              <max_vel>0.1</max_vel>
            </ode>
          </contact>
        </surface>
      </collision>

      <visual name='Body_RF2_c1_visual'>
        <pose>0 0 0 0 -0 0</pose>
        <geometry>
          <mesh>
            <scale>1 1 1</scale>
            <uri>model://DRC_hubo/meshes/Body_RF2_c1.STL</uri>
          </mesh>
        </geometry>
      </visual>

      <velocity_decay>
        <linear>0</linear>
        <angular>0</angular>
      </velocity_decay>
    </link>

    <joint name='RHAND_c1' type='revolute'>
      <child>Body_RF2_c1</child>
      <parent>Body_RF1</parent>
      <axis>
        <xyz>0 -1 0</xyz>
        <limit>
          <lower>0</lower>
          <upper>1.4708</upper>
          <effort>10000000</effort>
          <velocity>100</velocity>
        </limit>
        <dynamics>
          <damping>0.0003</damping> <friction>0.1</friction>
        </dynamics>
      </axis>
    </joint>

    <link name='Body_RF2_c2'>
      <pose>-0.0639103 -0.241705 -0.419941 -5.01647e-13 -0.7854 7.24549e-09</pose>
      <inertial>
        <pose>-0.0183473 5.73e-06 0.00742064 0 -0 0</pose>
        <mass>0.021949</mass>
        <inertia>
          <ixx>2.31e-05</ixx>
          <ixy>9e-06</ixy>
          <ixz>-4.6e-06</ixz>
          <iyy>7.09e-05</iyy>
          <iyz>-5e-06</iyz>
          <izz>6.69e-05</izz>
        </inertia>
      </inertial>

      <collision name='Body_RF2_c2_collision'>
        <pose>0 0 0 0 -0 0</pose>
        <geometry>
          <mesh>
            <scale>1 1 1</scale>
            <uri>model://DRC_hubo/meshes/Body_RF2_c2_col.STL</uri>
          </mesh>
        </geometry>
        <surface>
          <friction>
            <ode>
              <mu>1.0</mu>
              <mu2>1.0</mu2>
            </ode>
          </friction>
          <contact>
            <ode>
              <kp>10000000.0</kp>
              <kd>1.0</kd>
              <min_depth>0.001</min_depth>
              <max_vel>0.1</max_vel>
            </ode>
          </contact>
        </surface>
      </collision>

      <visual name='Body_RF2_c2_visual'>
        <pose>0 0 0 0 -0 0</pose>
        <geometry>
          <mesh>
            <scale>1 1 1</scale>
            <uri>model://DRC_hubo/meshes/Body_RF2_c2.STL</uri>
          </mesh>
        </geometry>
      </visual>

      <velocity_decay>
        <linear>0</linear>
        <angular>0</angular>
      </velocity_decay>
    </link>

    <joint name='RHAND_c2' type='revolute'>
      <child>Body_RF2_c2</child>
      <parent>Body_RF2_c1</parent>
      <axis>
        <xyz>0 -1 0</xyz>
        <limit>
          <lower>0</lower>
          <upper>1.4708</upper>
          <effort>10000000</effort>
          <velocity>100</velocity>
        </limit>
        <dynamics>
          <damping>0.0003</damping> <friction>0.1</friction>
        </dynamics>
      </axis>
    </joint>

    <link name='Body_RF2_c3'>
      <pose>-0.0921945 -0.241555 -0.448225 -4.98452e-13 -0.7854 7.24549e-09</pose>
      <inertial>
        <pose>-0.00112468 3.724e-05 0.00681838 0 -0 0</pose>
        <mass>0.0115</mass>
        <inertia>
          <ixx>7.2e-05</ixx>
          <ixy>1e-06</ixy>
          <ixz>2.9e-05</ixz>
          <iyy>1.67e-05</iyy>
          <iyz>1e-06</iyz>
          <izz>1.84e-05</izz>
        </inertia>
      </inertial>

      <collision name='Body_RF2_c3_collision'>
        <pose>0 0 0 0 -0 0</pose>
        <geometry>
          <mesh>
            <scale>1 1 1</scale>
            <uri>model://DRC_hubo/meshes/Body_RF2_c3_col.STL</uri>
          </mesh>
        </geometry>
        <surface>
          <friction>
            <ode>
              <mu>1.0</mu>
              <mu2>1.0</mu2>
            </ode>
          </friction>
          <contact>
            <ode>
              <kp>10000000.0</kp>
              <kd>1.0</kd>
              <min_depth>0.001</min_depth>
              <max_vel>0.1</max_vel>
            </ode>
          </contact>
        </surface>
      </collision>

      <visual name='Body_RF2_c3_visual'>
        <pose>0 0 0 0 -0 0</pose>
        <geometry>
          <mesh>
            <scale>1 1 1</scale>
            <uri>model://DRC_hubo/meshes/Body_RF2_c3.STL</uri>
          </mesh>
        </geometry>
      </visual>

      <velocity_decay>
        <linear>0</linear>
        <angular>0</angular>
      </velocity_decay>
    </link>

    <joint name='RHAND_c3' type='revolute'>
      <child>Body_RF2_c3</child>
      <parent>Body_RF2_c2</parent>
      <axis>
        <xyz>0 -1 0</xyz>
        <limit>
          <lower>0</lower>
          <upper>1.4708</upper>
          <effort>10000000</effort>
          <velocity>100</velocity>
        </limit>
        <dynamics>
          <damping>0.0003</damping> <friction>0.1</friction>
        </dynamics>
      </axis>
    </joint>

    <link name='Body_WST'>
      <pose>0 0 0 -2.6171e-17 9.9897e-17 2.0394e-07</pose>
      <inertial>
        <pose>-0.0142849 3.677e-05 0.167934 0 -0 0</pose>
        <mass>5.84383</mass>
        <inertia>
          <ixx>0.0381955</ixx>
          <ixy>-8.92e-06</ixy>
          <ixz>9.3e-06</ixz>
          <iyy>0.0129335</iyy>
          <iyz>1.362e-05</iyz>
          <izz>0.0406631</izz>
        </inertia>
      </inertial>

      <collision name='Body_WST_collision'>
        <pose>0 0 0 0 -0 0</pose>
        <geometry>
          <mesh>
            <scale>1 1 1</scale>
            <uri>model://DRC_hubo/meshes/Body_WST_col.STL</uri>
          </mesh>
        </geometry>
      </collision>

      <visual name='Body_WST_visual'>
        <pose>0 0 0 0 -0 0</pose>
        <geometry>
          <mesh>
            <scale>1 1 1</scale>
            <uri>model://DRC_hubo/meshes/Body_WST.STL</uri>
          </mesh>
        </geometry>
      </visual>

      <velocity_decay>
        <linear>0</linear>
        <angular>0</angular>
      </velocity_decay>

      <sensor name="imu" type="imu">
        <imu>
          <noise>
            <type>gaussian</type>
            <rate>
              <mean>0.0</mean>
              <stddev>2e-4</stddev>
              <bias_mean>0.0000075</bias_mean>
              <bias_stddev>0.0000008</bias_stddev>
            </rate>
            <accel>
              <mean>0.0</mean>
              <stddev>1.7e-2</stddev>
              <bias_mean>0.1</bias_mean>
              <bias_stddev>0.001</bias_stddev>
            </accel>
          </noise>
        </imu>
        <always_on>1</always_on>
        <update_rate>1000</update_rate>
      </sensor>
    </link>

    <joint name='WST' type='revolute'>
      <child>Body_WST</child>
      <parent>Body_TORSO</parent>
      <axis>
        <xyz>0 0 1</xyz>
        <limit>
          <lower>-3.14</lower>
          <upper>3.14</upper>
          <effort>10000000</effort>
          <velocity>100</velocity>
        </limit>
        <dynamics>
          <damping>30</damping> <friction>5</friction>
        </dynamics>
      </axis>
    </joint>

    <link name='Body_LHY'>
      <pose>-2.0394e-08 0.1 -2.6171e-18 1.60603e-15 9.9897e-17 2.0394e-07</pose>
      <inertial>
        <pose>-0.00935101 3.16e-05 0.0624095 0 -0 0</pose>
        <mass>0.928024</mass>
        <inertia>
          <ixx>0.00295486</ixx>
          <ixy>6.98e-06</ixy>
          <ixz>0.00078049</ixz>
          <iyy>0.00518702</iyy>
          <iyz>1.094e-05</iyz>
          <izz>0.00293613</izz>
        </inertia>
      </inertial>

      <collision name='Body_LHY_collision'>
        <pose>0 0 0 0 -0 0</pose>
        <geometry>
          <mesh>
            <scale>1 1 1</scale>
            <uri>model://DRC_hubo/meshes/Body_LHY_col.STL</uri>
          </mesh>
        </geometry>
      </collision>

      <visual name='Body_LHY_visual'>
        <pose>0 0 0 0 -0 0</pose>
        <geometry>
          <mesh>
            <scale>1 1 1</scale>
            <uri>model://DRC_hubo/meshes/Body_LHY.STL</uri>
          </mesh>
        </geometry>
      </visual>

      <velocity_decay>
        <linear>0</linear>
        <angular>0</angular>
      </velocity_decay>
    </link>

    <joint name='LHY' type='revolute'>
      <child>Body_LHY</child>
      <parent>Body_WST</parent>
      <axis>
        <xyz>0 0 1</xyz>
        <limit>
          <lower>-3.14</lower>
          <upper>3.14</upper>
          <effort>10000000</effort>
          <velocity>100</velocity>
        </limit>
        <dynamics>
          <damping>20</damping> <friction>2.5</friction>
        </dynamics>
      </axis>
    </joint>

    <link name='Body_LHR'>
      <pose>-2.0394e-08 0.1 -2.6171e-18 8.69259e-16 1.07592e-15 2.0394e-07</pose>
      <inertial>
        <pose>0.021225 0.00221228 0.00754947 0 -0 0</pose>
        <mass>1.59023</mass>
        <inertia>
          <ixx>0.00211844</ixx>
          <ixy>-7.043e-05</ixy>
          <ixz>-0.00032158</ixz>
          <iyy>0.00328567</iyy>
          <iyz>-2.583e-05</iyz>
          <izz>0.00327796</izz>
        </inertia>
      </inertial>

      <collision name='Body_LHR_collision'>
        <pose>0 0 0 0 -0 0</pose>
        <geometry>
          <mesh>
            <scale>1 1 1</scale>
            <uri>model://DRC_hubo/meshes/Body_LHR_col.STL</uri>
          </mesh>
        </geometry>
      </collision>

      <visual name='Body_LHR_visual'>
        <pose>0 0 0 0 -0 0</pose>
        <geometry>
          <mesh>
            <scale>1 1 1</scale>
            <uri>model://DRC_hubo/meshes/Body_LHR.STL</uri>
          </mesh>
        </geometry>
      </visual>

      <velocity_decay>
        <linear>0</linear>
        <angular>0</angular>
      </velocity_decay>
    </link>

    <joint name='LHR' type='revolute'>
      <child>Body_LHR</child>
      <parent>Body_LHY</parent>
      <axis>
        <xyz>1 0 0</xyz>
        <limit>
          <lower>-3.14</lower>
          <upper>3.14</upper>
          <effort>10000000</effort>
          <velocity>100</velocity>
        </limit>
        <dynamics>
          <damping>50</damping> <friction>2</friction>
        </dynamics>
      </axis>
    </joint>

    <link name='Body_LHP'>
      <pose>-2.0394e-08 0.1 -2.6171e-18 8.8313e-16 -1.1083e-17 2.0394e-07</pose>
      <inertial>
        <pose>0.00118459 0.0191546 -0.203184 0 -0 0</pose>
        <mass>6.71948</mass>
        <inertia>
          <ixx>0.141229</ixx>
          <ixy>-0.00025382</ixy>
          <ixz>-0.00860244</ixz>
          <iyy>0.137189</iyy>
          <iyz>0.00467915</iyz>
          <izz>0.0215948</izz>
        </inertia>
      </inertial>

      <collision name='Body_LHP_collision'>
        <pose>0 0 0 0 -0 0</pose>
        <geometry>
          <mesh>
            <scale>1 1 1</scale>
            <uri>model://DRC_hubo/meshes/Body_LHP_col.STL</uri>
          </mesh>
        </geometry>
      </collision>

      <visual name='Body_LHP_visual'>
        <pose>0 0 0 0 -0 0</pose>
        <geometry>
          <mesh>
            <scale>1 1 1</scale>
            <uri>model://DRC_hubo/meshes/Body_LHP.STL</uri>
          </mesh>
        </geometry>
      </visual>

      <velocity_decay>
        <linear>0</linear>
        <angular>0</angular>
      </velocity_decay>
    </link>

    <joint name='LHP' type='revolute'>
      <child>Body_LHP</child>
      <parent>Body_LHR</parent>
      <axis>
        <xyz>0 1 0</xyz>
        <limit>
          <lower>-3.14</lower>
          <upper>3.14</upper>
          <effort>10000000</effort>
          <velocity>100</velocity>
        </limit>
        <dynamics>
          <damping>50</damping> <friction>2</friction>
        </dynamics>
      </axis>
    </joint>

    <link name='Body_LKN'>
      <pose>-2.0394e-08 0.1 -0.38 2.44133e-15 -1.22103e-16 2.0394e-07</pose>
      <inertial>
        <pose>0.0183276 0.0136168 -0.202909 0 -0 0</pose>
        <mass>3.31308</mass>
        <inertia>
          <ixx>0.0505482</ixx>
          <ixy>1.49e-06</ixy>
          <ixz>0.00341835</ixz>
          <iyy>0.0477577</iyy>
          <iyz>-0.00179054</iyz>
          <izz>0.00783449</izz>
        </inertia>
      </inertial>

      <collision name='Body_LKN_collision'>
        <pose>0 0 0 0 -0 0</pose>
        <geometry>
          <mesh>
            <scale>1 1 1</scale>
	    <uri>model://DRC_hubo/meshes/Body_LKN_col.STL</uri>
          </mesh>
        </geometry>
      </collision>

      <visual name='Body_LKN_visual'>
        <pose>0 0 0 0 -0 0</pose>
        <geometry>
          <mesh>
            <scale>1 1 1</scale>
            <uri>model://DRC_hubo/meshes/Body_LKN.STL</uri>
          </mesh>
        </geometry>
      </visual>

      <velocity_decay>
        <linear>0</linear>
        <angular>0</angular>
      </velocity_decay>
    </link>

    <joint name='LKN' type='revolute'>
      <child>Body_LKN</child>
      <parent>Body_LHP</parent>
      <axis>
        <xyz>0 1 0</xyz>
        <limit>
          <lower>-3.14</lower>
          <upper>2.65</upper>
          <effort>10000000</effort>
          <velocity>100</velocity>
        </limit>
        <dynamics>
          <damping>150</damping> <friction>5</friction>
        </dynamics>
      </axis>
    </joint>

    <link name='Body_LAP'>
      <pose>-2.03736e-08 0.0999 -0.74 1.08093e-15 9.67497e-16 2.0394e-07</pose>
      <inertial>
        <pose>0.0172034 0.00229412 -0.00449716 0 -0 0</pose>
        <mass>1.46603</mass>
        <inertia>
          <ixx>0.00224197</ixx>
          <ixy>-6.068e-05</ixy>
          <ixz>-0.00068955</ixz>
          <iyy>0.00324527</iyy>
          <iyz>1.223e-05</iyz>
          <izz>0.0025331</izz>
        </inertia>
      </inertial>

      <collision name='Body_LAP_collision'>
        <pose>0 0 0 0 -0 0</pose>
        <geometry>
          <mesh>
            <scale>1 1 1</scale>
            <uri>model://DRC_hubo/meshes/Body_LAP_col.STL</uri>
          </mesh>
        </geometry>
      </collision>

      <visual name='Body_LAP_visual'>
        <pose>0 0 0 0 -0 0</pose>
        <geometry>
          <mesh>
            <scale>1 1 1</scale>
            <uri>model://DRC_hubo/meshes/Body_LAP.STL</uri>
          </mesh>
        </geometry>
      </visual>

      <velocity_decay>
        <linear>0</linear>
        <angular>0</angular>
      </velocity_decay>
    </link>

    <joint name='LAP' type='revolute'>
      <child>Body_LAP</child>
      <parent>Body_LKN</parent>
      <axis>
        <xyz>0 1 0</xyz>
        <limit>
          <lower>-3.14</lower>
          <upper>3.14</upper>
          <effort>10000000</effort>
          <velocity>100</velocity>
        </limit>
        <dynamics>
          <damping>2</damping> <friction>15</friction>
        </dynamics>
      </axis>
    </joint>

    <link name='Body_LAR'>
      <pose>-2.03736e-08 0.0999 -0.765 3.26773e-15 8.39877e-16 2.0394e-07</pose>
      <inertial>
        <pose>-0.00933053 0.00014696 -0.0217225 0 -0 0</pose>
        <mass>0.375042</mass>
        <inertia>
          <ixx>0.00040047</ixx>
          <ixy>-1.77e-06</ixy>
          <ixz>-0.00017001</ixz>
          <iyy>0.00119482</iyy>
          <iyz>8e-07</iyz>
          <izz>0.00101396</izz>
        </inertia>
      </inertial>

      <collision name='Body_LAR_collision'>
        <pose>0 0 0 0 -0 0</pose>
        <geometry>
          <mesh>
            <scale>1 1 1</scale>
            <uri>model://DRC_hubo/meshes/Body_LAR_col.STL</uri>
            <!--uri>model://DRC_hubo/meshes/Body_LAR_NEW.STL</uri-->
          </mesh>
        </geometry>
      </collision>

      <visual name='Body_LAR_visual'>
        <pose>0 0 0 0 -0 0</pose>
        <geometry>
          <mesh>
            <scale>1 1 1</scale>
            <!--uri>model://DRC_hubo/meshes/Body_LAR.STL</uri-->
            <uri>model://DRC_hubo/meshes/Body_LAR_NEW.STL</uri>
          </mesh>
        </geometry>
      </visual>

      <velocity_decay>
        <linear>0</linear>
        <angular>0</angular>
      </velocity_decay>
    </link>

    <joint name='LAR' type='revolute'>
      <child>Body_LAR</child>
      <parent>Body_LAP</parent>
      <axis>
        <xyz>1 0 0</xyz>
        <limit>
          <lower>-3.14</lower>
          <upper>3.14</upper>
          <effort>10000000</effort>
          <velocity>100</velocity>
        </limit>
        <dynamics>
          <damping>2</damping> <friction>1.5</friction>
        </dynamics>
      </axis>
    </joint>

    <link name='Body_LAFT'>
      <pose>-2.03736e-08 0.0999 -0.82 5.10673e-15 1.00302e-15 2.0394e-07</pose>
      <inertial>
        <pose>0.00122714 0.00808569 -0.0385989 0 -0 0</pose>
        <mass>1.29339</mass>
        <inertia>
          <ixx>0.00254979</ixx>
          <ixy>-8.23e-06</ixy>
          <ixz>3.972e-05</ixz>
          <iyy>0.00542362</iyy>
          <iyz>-3.93e-05</iyz>
          <izz>0.00773081</izz>
        </inertia>
      </inertial>

      <collision name='Body_LAFT_collision'>
        <pose>0 0 0 0 -0 0</pose>
        <geometry>
          <mesh>
            <scale>1 1 1</scale>
            <uri>model://DRC_hubo/meshes/Body_LAFT_col.STL</uri>
          </mesh>
        </geometry>
        <surface>
          <friction>
            <ode>
              <mu>1.0</mu>
             <mu2>1.0</mu2>
             <slip1>0.0</slip1>
             <slip2>0.0</slip2>
           </ode>
          </friction>
          <contact>
            <ode>
              <max_vel>0.00005</max_vel>
              <min_depth>0.004</min_depth>
            </ode>
          </contact>
        </surface>
        <max_contacts>20</max_contacts>
      </collision>

      <visual name='Body_LAFT_visual'>
        <pose>0 0 0 0 -0 0</pose>
        <geometry>
          <mesh>
            <scale>1 1 1</scale>
            <uri>model://DRC_hubo/meshes/Body_LAFT.STL</uri>
          </mesh>
        </geometry>
      </visual>

      <velocity_decay>
        <linear>0</linear>
        <angular>0</angular>
      </velocity_decay>
    </link>

    <joint name='LAFT' type='revolute'>
      <child>Body_LAFT</child>
      <parent>Body_LAR</parent>
      <axis>
        <xyz>0 0 -1</xyz>
        <limit>
          <lower>-0.001</lower>
          <upper>0.001</upper>
          <effort>10000000</effort>
          <velocity>100</velocity>
        </limit>
        <dynamics>
          <damping>2</damping> <friction>10</friction>
        </dynamics>
      </axis>
      <sensor name='FT_LAFT' type='force_torque'>
      </sensor>
    </joint>

    <link name='Body_LFUNI'>
      <pose>0.09 0.1798 -0.811 0 0 0</pose>
      <inertial>
        <pose>0.015121 1.0869E-07 -0.0067726 0 -0 0</pose>
        <mass>0.0470917</mass>
        <inertia>
          <ixx>8.5087e-05</ixx>
          <ixy>7.9111e-07</ixy>
          <ixz>-1.7854e-05</ixz>
          <iyy>6.9478e-05</iyy>
          <iyz>-1.1234e-07</iyz>
          <izz>1.2766e-04</izz>
        </inertia>
      </inertial>

      <collision name='Body_LFUNI_collision'>
        <pose>0 0 0 0 -0 0</pose>
        <geometry>
          <mesh>
            <scale>1 1 1</scale>
            <uri>model://DRC_hubo/meshes/Body_LFUNI.STL</uri>
          </mesh>
        </geometry>
        <surface>
          <contact>
            <ode>
              <max_vel>0.005</max_vel>
              <min_depth>0.001</min_depth>
            </ode>
          </contact>
        </surface>
      </collision>

      <visual name='Body_LFUNI_visual'>
        <pose>0 0 0 0 -0 0</pose>
        <geometry>
          <mesh>
            <scale>1 1 1</scale>
            <uri>model://DRC_hubo/meshes/Body_LFUNI.STL</uri>
          </mesh>
        </geometry>
      </visual>

      <velocity_decay>
        <linear>0</linear>
        <angular>0</angular>
      </velocity_decay>
    </link>

    <joint name='LFUNI' type='revolute'>
      <child>Body_LFUNI</child>
      <parent>Body_LAFT</parent>
      <axis>
        <xyz>-1 0 0</xyz>
        <limit>
          <lower>-1e+16</lower>
          <upper>1e+16</upper>
        </limit>
        <dynamics>
           <damping>0.05</damping> <friction>0.4</friction>
        </dynamics>
      </axis>
    </joint>

    <link name='Body_LFWH'>
      <pose>0.12 0.1798 -0.8239 0 1.4603 -3.1416</pose>
      <inertial>
        <pose>0 0 0 0 -0 0</pose>
        <mass>0.07657</mass>
        <inertia>
          <ixx>5.72e-04</ixx>
          <ixy>1e-08</ixy>
          <ixz>1e-08</ixz>
          <iyy>9.58e-04</iyy>
          <iyz>1e-08</iyz>
          <izz>5.72e-04</izz>
        </inertia>
      </inertial>
      <collision name='Body_LFWH_collision'>
        <pose>0 0 0 0 -0 0</pose>
        <geometry>
          <mesh>
            <scale>1 1 1</scale>
            <uri>model://DRC_hubo/meshes/Body_LFWHEEL.STL</uri>
          </mesh>
        </geometry>
        <surface>
          <friction>
            <ode>
              <mu>0.1</mu>
              <mu2>0.1</mu2>
              <slip1>0</slip1>
              <slip2>0</slip2>
            </ode>
          </friction>
          <contact>
            <ode>
              <kp>5e+13</kp>
              <kd>1.5</kd>
              <max_vel>0.0005</max_vel>
              <min_depth>0.005</min_depth>
            </ode>
          </contact>
        </surface>
      </collision>
      <visual name='Body_LFWH_visual'>
        <pose>0 0 0 0 -0 0</pose>
        <geometry>
          <mesh>
            <scale>1 1 1</scale>
            <uri>model://DRC_hubo/meshes/Body_LFWHEEL.STL</uri>
          </mesh>
        </geometry>
      </visual>
      <velocity_decay>
        <linear>0.001</linear>
        <angular>0.001</angular>
      </velocity_decay>
    </link>

    <joint name='LFWH' type='revolute'>
      <child>Body_LFWH</child>
      <parent>Body_LFUNI</parent>
      <axis>
        <xyz>0 -1 0</xyz>
        <limit>
          <lower>-1e+16</lower>
          <upper>1e+16</upper>
        </limit>
        <dynamics>
          <damping>1.2</damping> <friction>50</friction>
        </dynamics>
      </axis>
    </joint>

    <link name='Body_LWH'>
      <pose>0.045751 0.1 -0.51 7.5023e-16 -4.27413e-16 2.0394e-07</pose>
      <inertial>
        <pose>0 0.0800951 0 0 -0 0</pose>
        <mass>0.411522</mass>
        <inertia>
          <ixx>0.00038014</ixx>
          <ixy>1e-09</ixy>
          <ixz>1e-09</ixz>
          <iyy>0.0006581</iyy>
          <iyz>1e-09</iyz>
          <izz>0.00038014</izz>
        </inertia>
      </inertial>

      <collision name='Body_LWH_collision'>
        <pose>0 0 0 0 -0 0</pose>
        <geometry>
          <mesh>
            <scale>1 1 1</scale>
            <uri>model://DRC_hubo/meshes/Body_LWH_col.STL</uri>
          </mesh>
        </geometry>
        <surface>
          <friction>
            <ode>
              <mu>0.9</mu>
              <mu2>0.9</mu2>
              <slip1>0.0</slip1>
              <slip2>0.0</slip2>
            </ode>
          </friction>
          <contact>
            <ode>
              <max_vel>0.0005</max_vel>
              <min_depth>0.005</min_depth>
            </ode>
          </contact>
        </surface>
      </collision>

      <visual name='Body_LWH_visual'>
        <pose>0 0 0 0 -0 0</pose>
        <geometry>
          <mesh>
            <scale>1 1 1</scale>
            <uri>model://DRC_hubo/meshes/Body_LWH.STL</uri>
          </mesh>
        </geometry>
      </visual>

      <velocity_decay>
        <linear>0</linear>
        <angular>0</angular>
      </velocity_decay>
    </link>

    <joint name='LWH' type='revolute'>
      <child>Body_LWH</child>
      <parent>Body_LKN</parent>
      <axis>
        <xyz>0 1 0</xyz>
        <limit>
          <lower>-1e+16</lower>
          <upper>1e+16</upper>
          <effort>10000000</effort>
          <velocity>100</velocity>
        </limit>
        <dynamics>
          <damping>0.1</damping> <friction>30</friction>
        </dynamics>
      </axis>
    </joint>


    <link name='Body_RHY'>
      <pose>2.0394e-08 -0.1 2.6171e-18 5.91499e-16 5.02517e-16 2.0394e-07</pose>
      <inertial>
        <pose>-0.00935101 -3.16e-05 0.0624095 0 -0 0</pose>
        <mass>0.928024</mass>
        <inertia>
          <ixx>0.00295486</ixx>
          <ixy>-6.98e-06</ixy>
          <ixz>0.00078049</ixz>
          <iyy>0.00518702</iyy>
          <iyz>-1.094e-05</iyz>
          <izz>0.00293613</izz>
        </inertia>
      </inertial>

      <collision name='Body_RHY_collision'>
        <pose>0 0 0 0 -0 0</pose>
        <geometry>
          <mesh>
            <scale>1 1 1</scale>
            <uri>model://DRC_hubo/meshes/Body_RHY_col.STL</uri>
          </mesh>
        </geometry>
      </collision>

      <visual name='Body_RHY_visual'>
        <pose>0 0 0 0 -0 0</pose>
        <geometry>
          <mesh>
            <scale>1 1 1</scale>
            <uri>model://DRC_hubo/meshes/Body_RHY.STL</uri>
          </mesh>
        </geometry>
      </visual>

      <velocity_decay>
        <linear>0</linear>
        <angular>0</angular>
      </velocity_decay>
    </link>

    <joint name='RHY' type='revolute'>
      <child>Body_RHY</child>
      <parent>Body_WST</parent>
      <axis>
        <xyz>0 0 1</xyz>
        <limit>
          <lower>-3.14</lower>
          <upper>3.14</upper>
          <effort>10000000</effort>
          <velocity>100</velocity>
        </limit>
        <dynamics>
          <damping>20</damping> <friction>2.5</friction>
        </dynamics>
      </axis>
    </joint>

    <link name='Body_RHR'>
      <pose>2.0394e-08 -0.1 2.6171e-18 6.47176e-16 4.99918e-16 2.0394e-07</pose>
      <inertial>
        <pose>0.021225 -0.00221228 0.00754947 0 -0 0</pose>
        <mass>1.59023</mass>
        <inertia>
          <ixx>0.00211844</ixx>
          <ixy>7.043e-05</ixy>
          <ixz>-0.00032158</ixz>
          <iyy>0.00328567</iyy>
          <iyz>2.583e-05</iyz>
          <izz>0.00327796</izz>
        </inertia>
      </inertial>

      <collision name='Body_RHR_collision'>
        <pose>0 0 0 0 -0 0</pose>
        <geometry>
          <mesh>
            <scale>1 1 1</scale>
            <uri>model://DRC_hubo/meshes/Body_RHR_col.STL</uri>
          </mesh>
        </geometry>
      </collision>

      <visual name='Body_RHR_visual'>
        <pose>0 0 0 0 -0 0</pose>
        <geometry>
          <mesh>
            <scale>1 1 1</scale>
            <uri>model://DRC_hubo/meshes/Body_RHR.STL</uri>
          </mesh>
        </geometry>
      </visual>

      <velocity_decay>
        <linear>0</linear>
        <angular>0</angular>
      </velocity_decay>
    </link>

    <joint name='RHR' type='revolute'>
      <child>Body_RHR</child>
      <parent>Body_RHY</parent>
      <axis>
        <xyz>1 0 0</xyz>
        <limit>
          <lower>-3.14</lower>
          <upper>3.14</upper>
          <effort>10000000</effort>
          <velocity>100</velocity>
        </limit>
        <dynamics>
          <damping>50</damping> <friction>2</friction>
        </dynamics>
      </axis>
    </joint>

    <link name='Body_RHP'>
      <pose>2.0394e-08 -0.1 2.6171e-18 1.26845e-15 -1.31568e-15 2.0394e-07</pose>
      <inertial>
        <pose>0.00118459 -0.0191546 -0.203184 0 -0 0</pose>
        <mass>6.71948</mass>
        <inertia>
          <ixx>0.141229</ixx>
          <ixy>0.00025382</ixy>
          <ixz>-0.00860244</ixz>
          <iyy>0.137189</iyy>
          <iyz>-0.00467915</iyz>
          <izz>0.0215948</izz>
        </inertia>
      </inertial>

      <collision name='Body_RHP_collision'>
        <pose>0 0 0 0 -0 0</pose>
        <geometry>
          <mesh>
            <scale>1 1 1</scale>
            <uri>model://DRC_hubo/meshes/Body_RHP_col.STL</uri>
          </mesh>
        </geometry>
      </collision>

      <visual name='Body_RHP_visual'>
        <pose>0 0 0 0 -0 0</pose>
        <geometry>
          <mesh>
            <scale>1 1 1</scale>
            <uri>model://DRC_hubo/meshes/Body_RHP.STL</uri>
          </mesh>
        </geometry>
      </visual>

      <velocity_decay>
        <linear>0</linear>
        <angular>0</angular>
      </velocity_decay>
    </link>

    <joint name='RHP' type='revolute'>
      <child>Body_RHP</child>
      <parent>Body_RHR</parent>
      <axis>
        <xyz>0 1 0</xyz>
        <limit>
          <lower>-3.14</lower>
          <upper>3.14</upper>
          <effort>10000000</effort>
          <velocity>100</velocity>
        </limit>
        <dynamics>
          <damping>50</damping> <friction>2</friction>
        </dynamics>
      </axis>
    </joint>

    <link name='Body_RKN'>
      <pose>2.0394e-08 -0.1 -0.38 -9.34254e-16 -1.1182e-17 2.0394e-07</pose>
      <inertial>
        <pose>0.0183276 -0.0136168 -0.202909 0 -0 0</pose>
        <mass>3.31308</mass>
        <inertia>
          <ixx>0.0505482</ixx>
          <ixy>-1.49e-06</ixy>
          <ixz>0.00341835</ixz>
          <iyy>0.0477577</iyy>
          <iyz>0.00179054</iyz>
          <izz>0.00783449</izz>
        </inertia>
      </inertial>

      <collision name='Body_RKN_collision'>
        <pose>0 0 0 0 -0 0</pose>
        <geometry>
          <mesh>
            <scale>1 1 1</scale>
            <uri>model://DRC_hubo/meshes/Body_RKN_col.STL</uri>
          </mesh>
        </geometry>
      </collision>

      <visual name='Body_RKN_visual'>
        <pose>0 0 0 0 -0 0</pose>
        <geometry>
          <mesh>
            <scale>1 1 1</scale>
            <uri>model://DRC_hubo/meshes/Body_RKN.STL</uri>
          </mesh>
        </geometry>
      </visual>

      <velocity_decay>
        <linear>0</linear>
        <angular>0</angular>
      </velocity_decay>
    </link>

    <joint name='RKN' type='revolute'>
      <child>Body_RKN</child>
      <parent>Body_RHP</parent>
      <axis>
        <xyz>0 1 0</xyz>
        <limit>
          <lower>-3.14</lower>
          <upper>2.65</upper>
          <effort>10000000</effort>
          <velocity>100</velocity>
        </limit>
        <dynamics>
          <damping>150</damping> <friction>5</friction>
        </dynamics>
      </axis>
    </joint>

    <link name='Body_RAP'>
      <pose>2.03736e-08 -0.0999 -0.74 9.94146e-16 9.9838e-17 2.0394e-07</pose>
      <inertial>
        <pose>0.0172034 -0.00229412 -0.00449716 0 -0 0</pose>
        <mass>1.46603</mass>
        <inertia>
          <ixx>0.00224197</ixx>
          <ixy>6.068e-05</ixy>
          <ixz>-0.00068955</ixz>
          <iyy>0.00324527</iyy>
          <iyz>-1.223e-05</iyz>
          <izz>0.0025331</izz>
        </inertia>
      </inertial>

      <collision name='Body_RAP_collision'>
        <pose>0 0 0 0 -0 0</pose>
        <geometry>
          <mesh>
            <scale>1 1 1</scale>
            <uri>model://DRC_hubo/meshes/Body_RAP_col.STL</uri>
          </mesh>
        </geometry>
      </collision>

      <visual name='Body_RAP_visual'>
        <pose>0 0 0 0 -0 0</pose>
        <geometry>
          <mesh>
            <scale>1 1 1</scale>
            <uri>model://DRC_hubo/meshes/Body_RAP.STL</uri>
          </mesh>
        </geometry>
      </visual>

      <velocity_decay>
        <linear>0</linear>
        <angular>0</angular>
      </velocity_decay>
    </link>

    <joint name='RAP' type='revolute'>
      <child>Body_RAP</child>
      <parent>Body_RKN</parent>
      <axis>
        <xyz>0 1 0</xyz>
        <limit>
          <lower>-3.14</lower>
          <upper>3.14</upper>
          <effort>10000000</effort>
          <velocity>100</velocity>
        </limit>
        <dynamics>
          <damping>2</damping> <friction>15</friction>
        </dynamics>
      </axis>
    </joint>

    <link name='Body_RAR'>
      <pose>2.03736e-08 -0.0999 -0.765 9.25351e-16 1.33104e-15 2.0394e-07</pose>
      <inertial>
        <pose>-0.00933053 -0.00014696 -0.0217225 0 -0 0</pose>
        <mass>0.375042</mass>
        <inertia>
          <ixx>0.00040047</ixx>
          <ixy>1.77e-06</ixy>
          <ixz>-0.00017001</ixz>
          <iyy>0.00119482</iyy>
          <iyz>-8e-07</iyz>
          <izz>0.00101396</izz>
        </inertia>
      </inertial>

      <collision name='Body_RAR_collision'>
        <pose>0 0 0 0 -0 0</pose>
        <geometry>
          <mesh>
            <scale>1 1 1</scale>
            <uri>model://DRC_hubo/meshes/Body_RAR_col.STL</uri>
            <!--uri>model://DRC_hubo/meshes/Body_RAR_NEW.STL</uri-->
          </mesh>
        </geometry>
      </collision>

      <visual name='Body_RAR_visual'>
        <pose>0 0 0 0 -0 0</pose>
        <geometry>
          <mesh>
            <scale>1 1 1</scale>
            <!--uri>model://DRC_hubo/meshes/Body_RAR.STL</uri-->
            <uri>model://DRC_hubo/meshes/Body_RAR_NEW.STL</uri>
          </mesh>
        </geometry>
      </visual>

      <velocity_decay>
        <linear>0</linear>
        <angular>0</angular>
      </velocity_decay>
    </link>

    <joint name='RAR' type='revolute'>
      <child>Body_RAR</child>
      <parent>Body_RAP</parent>
      <axis>
        <xyz>1 0 0</xyz>
        <limit>
          <lower>-3.14</lower>
          <upper>3.14</upper>
          <effort>10000000</effort>
          <velocity>100</velocity>
        </limit>
        <dynamics>
          <damping>2</damping> <friction>1.5</friction>
        </dynamics>
      </axis>
    </joint>

    <link name='Body_RAFT'>
      <pose>2.03736e-08 -0.0999 -0.82 1.12216e-15 6.07618e-16 2.0394e-07</pose>
      <inertial>
        <pose>0.00122714 -0.00808569 -0.0385989 0 -0 0</pose>
        <mass>1.29339</mass>
        <inertia>
          <ixx>0.00254979</ixx>
          <ixy>8.23e-06</ixy>
          <ixz>3.972e-05</ixz>
          <iyy>0.00542362</iyy>
          <iyz>3.93e-05</iyz>
          <izz>0.00773081</izz>
        </inertia>
      </inertial>

      <collision name='Body_RAFT_collision'>
        <pose>0 0 0 0 -0 0</pose>
        <geometry>
          <mesh>
            <scale>1 1 1</scale>
            <uri>model://DRC_hubo/meshes/Body_RAFT_col.STL</uri>
          </mesh>
        </geometry>
        <surface>
          <friction>
            <ode>
              <mu>1.0</mu>
              <mu2>1.0</mu2>
              <slip1>0.0</slip1>
              <slip2>0.0</slip2>
            </ode>
          </friction>
          <contact>
            <ode>
              <max_vel>0.00005</max_vel>
              <min_depth>0.004</min_depth>
            </ode>
          </contact>
        </surface>
        <max_contacts>20</max_contacts>
      </collision>

      <visual name='Body_RAFT_visual'>
        <pose>0 0 0 0 -0 0</pose>
        <geometry>
          <mesh>
            <scale>1 1 1</scale>
            <uri>model://DRC_hubo/meshes/Body_RAFT.STL</uri>
          </mesh>
        </geometry>
      </visual>

      <velocity_decay>
        <linear>0</linear>
        <angular>0</angular>
      </velocity_decay>
    </link>

    <joint name='RAFT' type='revolute'>
      <child>Body_RAFT</child>
      <parent>Body_RAR</parent>
      <axis>
        <xyz>0 0 1</xyz>
        <limit>
          <lower>-0.001</lower>
          <upper>0.001</upper>
          <effort>10000000</effort>
          <velocity>100</velocity>
        </limit>
        <dynamics>
          <damping>2</damping> <friction>10</friction>
        </dynamics>
      </axis>
      <sensor name='FT_RAFT' type='force_torque'>
      </sensor>
    </joint>

    <link name='Body_RFUNI'>
      <pose>0.09 -0.1798 -0.811 0 0 0</pose>
      <inertial>
        <pose>0.015121 1.0869e-07 -0.0067726 0 -0 0</pose>
        <mass>0.0470917</mass>
        <inertia>
          <ixx>8.5087e-05</ixx>
          <ixy>7.9111e-07</ixy>
          <ixz>-1.7854e-05</ixz>
          <iyy>6.9478e-05</iyy>
          <iyz>-1.1234e-07</iyz>
          <izz>1.2766e-04</izz>
        </inertia>
      </inertial>

      <collision name='Body_RFUNI_collision'>
        <pose>0 0 0 0 -0 0</pose>
        <geometry>
          <mesh>
            <scale>1 1 1</scale>
            <uri>model://DRC_hubo/meshes/Body_RFUNI.STL</uri>
          </mesh>
        </geometry>
        <surface>
          <contact>
            <ode>
              <max_vel>0.005</max_vel>
              <min_depth>0.001</min_depth>
            </ode>
          </contact>
        </surface>
      </collision>

      <visual name='Body_RFUNI_visual'>
        <pose>0 0 0 0 -0 0</pose>
        <geometry>
          <mesh>
            <scale>1 1 1</scale>
            <uri>model://DRC_hubo/meshes/Body_RFUNI.STL</uri>
          </mesh>
        </geometry>
      </visual>

      <velocity_decay>
        <linear>0</linear>
        <angular>0</angular>
      </velocity_decay>
    </link>

    <joint name='RFUNI' type='revolute'>
      <child>Body_RFUNI</child>
      <parent>Body_RAFT</parent>
      <axis>
        <xyz>-1 0 0</xyz>
        <limit>
          <lower>-1e+16</lower>
          <upper>1e+16</upper>
        </limit>
        <dynamics>
           <damping>0.05</damping> <friction>0.4</friction>
        </dynamics>
      </axis>
    </joint>

    <link name='Body_RFWH'>
      <pose>0.12 -0.1798 -0.8239 0 1.4603 -3.1416</pose>
      <inertial>
        <pose>0 0 0 0 -0 0</pose>
        <mass>0.07657</mass>
        <inertia>
          <ixx>5.72e-04</ixx>
          <ixy>1e-08</ixy>
          <ixz>1e-08</ixz>
          <iyy>9.58e-04</iyy>
          <iyz>1e-08</iyz>
          <izz>5.72e-04</izz>
        </inertia>
      </inertial>

      <collision name='Body_RFWH_collision'>
        <pose>0 0 0 0 -0 0</pose>
        <geometry>
          <mesh>
            <scale>1 1 1</scale>
            <uri>model://DRC_hubo/meshes/Body_RFWHEEL.STL</uri>
          </mesh>
        </geometry>
        <surface>
          <friction>
            <ode>
              <mu>0.1</mu>
              <mu2>0.1</mu2>
              <slip1>0</slip1>
              <slip2>0</slip2>
            </ode>
          </friction>
          <contact>
            <ode>
              <kp>5e+13</kp>
              <kd>1.5</kd>
              <max_vel>0.0005</max_vel>
              <min_depth>0.005</min_depth>
            </ode>
          </contact>
        </surface>
      </collision>

      <visual name='Body_RFWH_visual'>
        <pose>0 0 0 0 -0 0</pose>
        <geometry>
          <mesh>
            <scale>1 1 1</scale>
            <uri>model://DRC_hubo/meshes/Body_RFWHEEL.STL</uri>
          </mesh>
        </geometry>
      </visual>

      <velocity_decay>
        <linear>0.001</linear>
        <angular>0.001</angular>
      </velocity_decay>
    </link>

    <joint name='RFWH' type='revolute'>
      <child>Body_RFWH</child>
      <parent>Body_RFUNI</parent>
      <axis>
        <xyz>0 -1 0</xyz>
        <limit>
          <lower>-1e+16</lower>
          <upper>1e+16</upper>
        </limit>
        <dynamics>
          <damping>1.2</damping> <friction>50</friction>
        </dynamics>
      </axis>
    </joint>


    <link name='Body_RWH'>
      <pose>0.045751 -0.1 -0.51 1.45115e-15 -1.49962e-16 2.0394e-07</pose>
      <inertial>
        <pose>0 -0.0800951 0 0 -0 0</pose>
        <mass>0.411522</mass>
        <inertia>
          <ixx>0.00038014</ixx>
          <ixy>-1e-09</ixy>
          <ixz>1e-09</ixz>
          <iyy>0.0006581</iyy>
          <iyz>-1e-09</iyz>
          <izz>0.00038014</izz>
        </inertia>
      </inertial>

      <collision name='Body_RWH_collision'>
        <pose>0 0 0 0 -0 0</pose>
        <geometry>
          <mesh>
            <scale>1 1 1</scale>
            <uri>model://DRC_hubo/meshes/Body_RWH_col.STL</uri>
          </mesh>
        </geometry>        
        <surface>
          <friction>
            <ode>
              <mu>0.9</mu>
              <mu2>0.9</mu2>
              <slip1>0.0</slip1>
              <slip2>0.0</slip2>
            </ode>
          </friction>
          <contact>
            <ode>
              <max_vel>0.0005</max_vel>
              <min_depth>0.005</min_depth>
            </ode>
          </contact>
        </surface>
      </collision>

      <visual name='Body_RWH_visual'>
        <pose>0 0 0 0 -0 0</pose>
        <geometry>
          <mesh>
            <scale>1 1 1</scale>
            <uri>model://DRC_hubo/meshes/Body_RWH.STL</uri>
          </mesh>
        </geometry>
      </visual>

      <velocity_decay>
        <linear>0</linear>
        <angular>0</angular>
      </velocity_decay>
    </link>

    <joint name='RWH' type='revolute'>
      <child>Body_RWH</child>
      <parent>Body_RKN</parent>
      <axis>
        <xyz>0 1 0</xyz>
        <limit>
          <lower>-1e+16</lower>
          <upper>1e+16</upper>
          <effort>10000000</effort>
          <velocity>100</velocity>
        </limit>
        <dynamics>
          <damping>0.1</damping> <friction>30</friction>
        </dynamics>
      </axis>
    </joint>

    <joint name="head_joint" type="prismatic">

      <child>DRC_head::Body_Head</child>
<!--
      <child>DRC_head_kinect::Body_Head</child>
-->
      <parent>Body_TORSO</parent>
      <axis>
        <xyz>0 0 1</xyz>
        <limit>
          <upper>0</upper>
          <lower>-0</lower>
        </limit>
      </axis>
    </joint>

    <plugin name="drc_plugin" filename="/home/hubo/catkin_ws/devel/lib/libdrc_plugin.so"/>

    <include>

      <uri>model://DRC_head</uri>
<!--
      <uri>model://DRC_head_kinect</uri>
-->
      <pose>0.055 0 0.521 0 0 0</pose>
    <include>







  </model>
</sdf>
